Workbook
Name cycle: #REF!

Sheet 1-200关设定
B1: level | C1: difficulty | D1: 3档位通关率 | E1: 加入机制 | F1: 解锁系统（当前关卡，包括开始局外和关卡结束） | G1: Block2x2 | H1: Objective1 | I1: Pool | J1: GateLeft | K1: GateRight | L1: GateTop | M1: Gate | N1: Snake | O1: Key | P1: Screw | Q1: SecretItem | R1: Triangle | S1: Link | T1: LinkDown | U1: LinkRight | V1: Special Count | W1: Color Count | X1: 死亡分布类型 | Y1: 死亡分布
A2: 基础教学 | B2: 1 | C2: normal | D2: 1 | G2: 0 | H2: 0 | I2: 0 | J2: 0 | K2: 0 | L2: 0 | M2: 0 | N2: 0 | O2: 0 | P2: 0 | Q2: 0 | R2: 0 | S2: 0 | T2: 0 | U2: 0 | V2: 0 | W2: 2 | X2: 1 | Y2: 0.1,0.1,0.1,0.1,0.1,0.1,0.1,0.1,0.1,0.1
B3: 2 | C3: normal | D3: 1 | G3: 0 | H3: 0 | I3: 0 | J3: 0 | K3: 0 | L3: 0 | M3: 0 | N3: 0 | O3: 0 | P3: 0 | Q3: 0 | R3: 0 | S3: 0 | T3: 0 | U3: 0 | V3: 0 | W3: 3 | X3: 1 | Y3: 0.1,0.1,0.1,0.1,0.1,0.1,0.1,0.1,0.1,0.1
B4: 3 | C4: normal | D4: 1 | E4: 合成教学 | G4: 0 | H4: 0 | I4: 0 | J4: 0 | K4: 0 | L4: 0 | M4: 0 | N4: 0 | O4: 0 | P4: 0 | Q4: 0 | R4: 0 | S4: 0 | T4: 0 | U4: 0 | V4: 0 | W4: 3 | X4: 1 | Y4: 0.1,0.1,0.1,0.1,0.1,0.1,0.1,0.1,0.1,0.1
B5: 4 | C5: normal | D5: 1 | G5: 0 | H5: 0 | I5: 0 | J5: 0 | K5: 0 | L5: 0 | M5: 0 | N5: 0 | O5: 0 | P5: 0 | Q5: 0 | R5: 0 | S5: 0 | T5: 0 | U5: 0 | V5: 0 | W5: 3 | X5: 1 | Y5: 0.1,0.1,0.1,0.1,0.1,0.1,0.1,0.1,0.1,0.1
B6: 5 | C6: normal | D6: 1 | E6: 大方块 | G6: 1 | H6: 0 | I6: 0 | J6: 0 | K6: 0 | L6: 0 | M6: 0 | N6: 0 | O6: 0 | P6: 0 | Q6: 0 | R6: 0 | S6: 0 | T6: 0 | U6: 0 | V6: 1 | W6: 3 | X6: 1 | Y6: 0.1,0.1,0.1,0.1,0.1,0.1,0.1,0.1,0.1,0.1
B7: 6 | C7: normal | D7: 0.9 | G7: 1 | H7: 0 | I7: 0 | J7: 0 | K7: 0 | L7: 0 | M7: 0 | N7: 0 | O7: 0 | P7: 0 | Q7: 0 | R7: 0 | S7: 0 | T7: 0 | U7: 0 | V7: 1 | W7: 4 | X7: 1 | Y7: 0.1,0.1,0.1,0.1,0.1,0.1,0.1,0.1,0.1,0.1
B8: 7 | C8: normal | D8: 1 | E8: 问号炮台 | G8: 0 | H8: 0 | I8: 0 | J8: 0 | K8: 0 | L8: 0 | M8: 0 | N8: 0 | O8: 0 | P8: 0 | Q8: 1 | R8: 0 | S8: 0 | T8: 0 | U8: 0 | V8: 1 | W8: 3 | X8: 1 | Y8: 0.1,0.1,0.1,0.1,0.1,0.1,0.1,0.1,0.1,0.1
B9: 8 | C9: normal | D9: 0.9 | G9: 0 | H9: 0 | I9: 0 | J9: 0 | K9: 0 | L9: 0 | M9: 0 | N9: 0 | O9: 0 | P9: 0 | Q9: 1 | R9: 0 | S9: 0 | T9: 0 | U9: 0 | V9: 1 | W9: 4 | X9: 1 | Y9: 0.1,0.1,0.1,0.1,0.1,0.1,0.1,0.1,0.1,0.1
B10: 9 | C10: normal | D10: 0.9 | G10: 1 | H10: 0 | I10: 0 | J10: 0 | K10: 0 | L10: 0 | M10: 0 | N10: 0 | O10: 0 | P10: 0 | Q10: 1 | R10: 0 | S10: 0 | T10: 0 | U10: 0 | V10: 2 | W10: 4 | X10: 1 | Y10: 0.1,0.1,0.1,0.1,0.1,0.1,0.1,0.1,0.1,0.1
B11: 10 | C11: normal | D11: 1 | E11: 三角炮台 | G11: 0 | H11: 0 | I11: 0 | J11: 0 | K11: 0 | L11: 0 | M11: 0 | N11: 0 | O11: 0 | P11: 0 | Q11: 0 | R11: 1 | S11: 0 | T11: 0 | U11: 0 | V11: 1 | W11: 3 | X11: 1 | Y11: 0.1,0.1,0.1,0.1,0.1,0.1,0.1,0.1,0.1,0.1
B12: 11 | C12: normal | D12: 0.9 | G12: 1 | H12: 0 | I12: 0 | J12: 0 | K12: 0 | L12: 0 | M12: 0 | N12: 0 | O12: 0 | P12: 0 | Q12: 0 | R12: 1 | S12: 0 | T12: 0 | U12: 0 | V12: 2 | W12: 4 | X12: 1 | Y12: 0.1,0.1,0.1,0.1,0.1,0.1,0.1,0.1,0.1,0.1
B13: 12 | C13: normal | D13: 0.9 | G13: 1 | H13: 0 | I13: 0 | J13: 0 | K13: 0 | L13: 0 | M13: 0 | N13: 0 | O13: 0 | P13: 0 | Q13: 1 | R13: 0 | S13: 0 | T13: 0 | U13: 0 | V13: 2 | W13: 4 | X13: 1 | Y13: 0.1,0.1,0.1,0.1,0.1,0.1,0.1,0.1,0.1,0.1
B14: 13 | C14: normal | D14: 0.9 | E14: 磁铁道具指引 | G14: 0 | H14: 0 | I14: 0 | J14: 0 | K14: 0 | L14: 0 | M14: 0 | N14: 0 | O14: 0 | P14: 0 | Q14: 0 | R14: 0 | S14: 0 | T14: 0 | U14: 0 | V14: 0 | W14: 5 | X14: 1 | Y14: 0.1,0.1,0.1,0.1,0.1,0.1,0.1,0.1,0.1,0.1
B15: 14 | C15: hard | D15: 0.7 | G15: 1 | H15: 0 | I15: 0 | J15: 0 | K15: 0 | L15: 0 | M15: 0 | N15: 0 | O15: 0 | P15: 0 | Q15: 1 | R15: 1 | S15: 0 | T15: 0 | U15: 0 | V15: 3 | W15: 4 | X15: 1 | Y15: 0.1,0.1,0.1,0.1,0.1,0.1,0.1,0.1,0.1,0.1
A16: 三角炮台 | B16: 15 | C16: normal | D16: 0.85 | F16: 开始：新手签到+每日签到 | G16: 0 | H16: 0 | I16: 0 | J16: 0 | K16: 0 | L16: 0 | M16: 0 | N16: 0 | O16: 0 | P16: 0 | Q16: 0 | R16: 1 | S16: 0 | T16: 0 | U16: 0 | V16: 1 | W16: 4 | X16: 1 | Y16: 0.1,0.1,0.1,0.1,0.1,0.1,0.1,0.1,0.1,0.1
B17: 16 | C17: normal | D17: 0.85 | E17: 得分小猪 | G17: 0 | H17: 1 | I17: 0 | J17: 0 | K17: 0 | L17: 0 | M17: 0 | N17: 0 | O17: 0 | P17: 0 | Q17: 0 | R17: 0 | S17: 0 | T17: 0 | U17: 0 | V17: 0 | W17: 3 | X17: 2 | Y17: 0,0.2,0,0.2,0,0.2,0,0.2,0,0.2
B18: 17 | C18: normal | D18: 0.85 | G18: 1 | H18: 0 | I18: 0 | J18: 0 | K18: 0 | L18: 0 | M18: 0 | N18: 0 | O18: 0 | P18: 0 | Q18: 0 | R18: 1 | S18: 0 | T18: 0 | U18: 0 | V18: 2 | W18: 4 | X18: 3 | Y18: 0,0,0.018,0.042,0.109,0.159,0.213,0.282,0.121,0.056
B19: 18 | C19: normal | D19: 0.85 | E19: 魔法棒道具指引 | G19: 0 | H19: 0 | I19: 0 | J19: 0 | K19: 0 | L19: 0 | M19: 0 | N19: 0 | O19: 0 | P19: 0 | Q19: 1 | R19: 1 | S19: 0 | T19: 0 | U19: 0 | V19: 2 | W19: 5 | X19: 4 | Y19: 0,0,0.125,0.25,0.125,0,0.125,0.25,0.125,0
B20: 19 | C20: hard | D20: 0.6 | F20: 结算：双倍金币出现，fail offer | G20: 0 | H20: 1 | I20: 0 | J20: 0 | K20: 0 | L20: 0 | M20: 0 | N20: 0 | O20: 0 | P20: 0 | Q20: 0 | R20: 1 | S20: 0 | T20: 0 | U20: 0 | V20: 1 | W20: 5 | X20: 5 | Y20: 0,0,0.027,0.126,0.31,0.537,0,0,0,0
B21: 20 | C21: superhard | D21: 0.4 | G21: 1 | H21: 1 | I21: 0 | J21: 0 | K21: 0 | L21: 0 | M21: 0 | N21: 0 | O21: 0 | P21: 0 | Q21: 1 | R21: 1 | S21: 0 | T21: 0 | U21: 0 | V21: 3 | W21: 4 | X21: 6 | Y21: 0,0,0,0,0.025,0.084,0.183,0.52,0.188,0
A22: 相连炮台 | B22: 21 | C22: normal | D22: 1 | E22: 相连炮台 | G22: 0 | H22: 0 | I22: 0 | J22: 0 | K22: 0 | L22: 0 | M22: 0 | N22: 0 | O22: 0 | P22: 0 | Q22: 0 | R22: 0 | S22: 1 | T22: 1 | U22: 1 | V22: 1 | W22: 3 | X22: 1 | Y22: 0.1,0.1,0.1,0.1,0.1,0.1,0.1,0.1,0.1,0.1
B23: 22 | C23: normal | D23: 0.85 | G23: 0 | H23: 0 | I23: 0 | J23: 0 | K23: 0 | L23: 0 | M23: 0 | N23: 0 | O23: 0 | P23: 0 | Q23: 0 | R23: 0 | S23: 1 | T23: 1 | U23: 1 | V23: 1 | W23: 4 | X23: 1 | Y23: 0.1,0.1,0.1,0.1,0.1,0.1,0.1,0.1,0.1,0.1
B24: 23 | C24: normal | D24: 0.85 | E24: 锤子道具指引 | G24: 0 | H24: 0 | I24: 0 | J24: 0 | K24: 0 | L24: 0 | M24: 0 | N24: 0 | O24: 0 | P24: 0 | Q24: 0 | R24: 1 | S24: 0 | T24: 0 | U24: 0 | V24: 1 | W24: 4 | X24: 2 | Y24: 0,0.2,0,0.2,0,0.2,0,0.2,0,0.2
B25: 24 | C25: hard | D25: 0.6 | F25: 结算：强制出现广告+免广告系统推送+商店上架免广告pass | G25: 1 | H25: 0 | I25: 0 | J25: 0 | K25: 0 | L25: 0 | M25: 0 | N25: 0 | O25: 0 | P25: 0 | Q25: 0 | R25: 1 | S25: 1 | T25: 1 | U25: 1 | V25: 3 | W25: 5 | X25: 2 | Y25: 0,0.2,0,0.2,0,0.2,0,0.2,0,0.2
B26: 25 | C26: normal | D26: 0.85 | F26: 开始：任务 | G26: 0 | H26: 0 | I26: 0 | J26: 0 | K26: 0 | L26: 0 | M26: 0 | N26: 0 | O26: 0 | P26: 0 | Q26: 1 | R26: 1 | S26: 0 | T26: 0 | U26: 0 | V26: 2 | W26: 3 | X26: 1 | Y26: 0.1,0.1,0.1,0.1,0.1,0.1,0.1,0.1,0.1,0.1
B27: 26 | C27: normal | D27: 0.85 | E27: 回溯道具指引 | G27: 0 | H27: 0 | I27: 0 | J27: 0 | K27: 0 | L27: 0 | M27: 0 | N27: 0 | O27: 0 | P27: 0 | Q27: 1 | R27: 0 | S27: 1 | T27: 1 | U27: 1 | V27: 2 | W27: 4 | X27: 1 | Y27: 0.1,0.1,0.1,0.1,0.1,0.1,0.1,0.1,0.1,0.1
B28: 27 | C28: hard | D28: 0.6 | G28: 1 | H28: 0 | I28: 0 | J28: 0 | K28: 0 | L28: 0 | M28: 0 | N28: 0 | O28: 0 | P28: 0 | Q28: 1 | R28: 1 | S28: 1 | T28: 1 | U28: 1 | V28: 4 | W28: 4 | X28: 2 | Y28: 0,0.2,0,0.2,0,0.2,0,0.2,0,0.2
B29: 28 | C29: normal | D29: 0.85 | G29: 0 | H29: 0 | I29: 0 | J29: 0 | K29: 0 | L29: 0 | M29: 0 | N29: 0 | O29: 0 | P29: 0 | Q29: 1 | R29: 1 | S29: 0 | T29: 0 | U29: 0 | V29: 2 | W29: 3 | X29: 1 | Y29: 0.1,0.1,0.1,0.1,0.1,0.1,0.1,0.1,0.1,0.1
B30: 29 | C30: normal | D30: 0.85 | G30: 0 | H30: 1 | I30: 0 | J30: 0 | K30: 0 | L30: 0 | M30: 0 | N30: 0 | O30: 0 | P30: 0 | Q30: 1 | R30: 0 | S30: 1 | T30: 1 | U30: 1 | V30: 2 | W30: 4 | X30: 1 | Y30: 0.1,0.1,0.1,0.1,0.1,0.1,0.1,0.1,0.1,0.1
B31: 30 | C31: superhard | D31: 0.4 | G31: 0 | H31: 0 | I31: 0 | J31: 0 | K31: 0 | L31: 0 | M31: 0 | N31: 0 | O31: 0 | P31: 0 | Q31: 0 | R31: 1 | S31: 1 | T31: 1 | U31: 1 | V31: 2 | W31: 4 | X31: 3 | Y31: 0,0,0.018,0.042,0.109,0.159,0.213,0.282,0.121,0.056
B32: 31 | C32: normal | D32: 0.85 | G32: 1 | H32: 0 | I32: 0 | J32: 0 | K32: 0 | L32: 0 | M32: 0 | N32: 0 | O32: 0 | P32: 0 | Q32: 0 | R32: 1 | S32: 0 | T32: 0 | U32: 0 | V32: 2 | W32: 4 | X32: 1 | Y32: 0.1,0.1,0.1,0.1,0.1,0.1,0.1,0.1,0.1,0.1
B33: 32 | C33: normal | D33: 0.85 | G33: 0 | H33: 0 | I33: 0 | J33: 0 | K33: 0 | L33: 0 | M33: 0 | N33: 0 | O33: 0 | P33: 0 | Q33: 0 | R33: 0 | S33: 1 | T33: 1 | U33: 1 | V33: 1 | W33: 3 | X33: 1 | Y33: 0.1,0.1,0.1,0.1,0.1,0.1,0.1,0.1,0.1,0.1
B34: 33 | C34: normal | D34: 0.85 | G34: 0 | H34: 0 | I34: 0 | J34: 0 | K34: 0 | L34: 0 | M34: 0 | N34: 0 | O34: 0 | P34: 0 | Q34: 0 | R34: 1 | S34: 1 | T34: 1 | U34: 1 | V34: 2 | W34: 4 | X34: 2 | Y34: 0,0.2,0,0.2,0,0.2,0,0.2,0,0.2
A35: 门 | B35: 34 | C35: normal | D35: 0.85 | E35: 门 | G35: 0 | H35: 0 | I35: 0 | J35: 1 | K35: 0 | L35: 0 | M35: 1 | N35: 0 | O35: 0 | P35: 0 | Q35: 0 | R35: 0 | S35: 0 | T35: 0 | U35: 0 | V35: 1 | W35: 3 | X35: 1 | Y35: 0.1,0.1,0.1,0.1,0.1,0.1,0.1,0.1,0.1,0.1
B36: 35 | C36: normal | D36: 0.85 | F36: 开始：通行证+商店上架通行证 | G36: 0 | H36: 0 | I36: 0 | J36: 1 | K36: 1 | L36: 0 | M36: 1 | N36: 0 | O36: 0 | P36: 0 | Q36: 1 | R36: 0 | S36: 0 | T36: 0 | U36: 0 | V36: 2 | W36: 4 | X36: 1 | Y36: 0.1,0.1,0.1,0.1,0.1,0.1,0.1,0.1,0.1,0.1
B37: 36 | C37: normal | D37: 0.85 | G37: 0 | H37: 0 | I37: 0 | J37: 0 | K37: 0 | L37: 1 | M37: 1 | N37: 0 | O37: 0 | P37: 0 | Q37: 0 | R37: 0 | S37: 1 | T37: 1 | U37: 1 | V37: 2 | W37: 3 | X37: 2 | Y37: 0,0.2,0,0.2,0,0.2,0,0.2,0,0.2
B38: 37 | C38: normal | D38: 0.85 | G38: 0 | H38: 0 | I38: 0 | J38: 0 | K38: 1 | L38: 0 | M38: 1 | N38: 0 | O38: 0 | P38: 0 | Q38: 0 | R38: 1 | S38: 0 | T38: 0 | U38: 0 | V38: 2 | W38: 4 | X38: 1 | Y38: 0.1,0.1,0.1,0.1,0.1,0.1,0.1,0.1,0.1,0.1
B39: 38 | C39: hard | D39: 0.6 | G39: 0 | H39: 0 | I39: 0 | J39: 1 | K39: 1 | L39: 0 | M39: 1 | N39: 0 | O39: 0 | P39: 0 | Q39: 0 | R39: 1 | S39: 1 | T39: 1 | U39: 1 | V39: 3 | W39: 4 | X39: 1 | Y39: 0.1,0.1,0.1,0.1,0.1,0.1,0.1,0.1,0.1,0.1
B40: 39 | C40: normal | D40: 0.85 | G40: 0 | H40: 1 | I40: 0 | J40: 0 | K40: 0 | L40: 0 | M40: 0 | N40: 0 | O40: 0 | P40: 0 | Q40: 0 | R40: 1 | S40: 1 | T40: 1 | U40: 1 | V40: 2 | W40: 4 | X40: 2 | Y40: 0,0.2,0,0.2,0,0.2,0,0.2,0,0.2
...

Sheet 总体配置
A1: 备注 | B1: level | C1: difficulty | D1: 3档位通关率 | E1: 关卡解锁（该关卡） | F1: 解锁系统（当前处于改关卡状态，还未进入时） | G1: Total Count | H1: Color Count | I1: Special Block | J1: F_endurance | K1: F_search | L1: F_strategy | M1: RLD Score | N1: RLD_Label | O1: 死亡类型 | P1: 死亡分布
A2: 基础教学 | B2: 1 | C2: normal | D2: 1 | G2: 200 | H2: 2 | I2: 1 | J2: =IF(G2="","",1-EXP(-G2/参数配置!O6)) -> 0.22119922 | K2: =IF(H2="","",((H2-2)/4)^2) -> 0 | L2: =IF(I2="","",1-2^(-I2)) -> 0.5 | M2: =IF(G2="","",(参数配置!O2*K2+参数配置!O3*(J2-(1-EXP(-200/参数配置!O6)))/((1-EXP(-1500/参数配置!O6))-(1-EXP(-200/参数配置!O6)))+参数配置!O4*(L2/(1-2^(-5)))+参数配置!O5*K2*(J2-(1-EXP(-200/参数配置!O6)))/((1-EXP(-1500/参数配置!O6))-(1-EXP(-200/参数配置!O6))))*100) -> 7.7419355 | N2: {=IF(G2>0,RLD_Label(G2,H2,I2),"")} -> #NAME? | O2: 1 | P2: =IFERROR(INDEX(参数配置!B:B,MATCH(O2,参数配置!A:A,0)),"") -> 平缓推进
B3: 2 | C3: normal | D3: 1 | G3: 320 | H3: 3 | I3: 0 | J3: =IF(G3="","",1-EXP(-G3/参数配置!O7)) -> #DIV/0! | K3: =IF(H3="","",((H3-2)/4)^2) -> 0.0625 | L3: =IF(I3="","",1-2^(-I3)) -> 0 | M3: =IF(G3="","",(参数配置!O3*K3+参数配置!O4*(J3-(1-EXP(-200/参数配置!O7)))/((1-EXP(-1500/参数配置!O7))-(1-EXP(-200/参数配置!O7)))+参数配置!O5*(L3/(1-2^(-5)))+参数配置!O6*K3*(J3-(1-EXP(-200/参数配置!O7)))/((1-EXP(-1500/参数配置!O7))-(1-EXP(-200/参数配置!O7))))*100) -> #DIV/0! | N3: {=IF(G3>0,RLD_Label(G3,H3,I3),"")} -> #NAME? | O3: 1 | P3: =IFERROR(INDEX(参数配置!B:B,MATCH(O3,参数配置!A:A,0)),"") -> 平缓推进
B4: 3 | C4: normal | D4: 1 | E4: 合成教学 | G4: 400 | H4: 3 | I4: 0 | J4: =IF(G4="","",1-EXP(-G4/参数配置!O8)) -> #DIV/0! | K4: =IF(H4="","",((H4-2)/4)^2) -> 0.0625 | L4: =IF(I4="","",1-2^(-I4)) -> 0 | M4: =IF(G4="","",(参数配置!O4*K4+参数配置!O5*(J4-(1-EXP(-200/参数配置!O8)))/((1-EXP(-1500/参数配置!O8))-(1-EXP(-200/参数配置!O8)))+参数配置!O6*(L4/(1-2^(-5)))+参数配置!O7*K4*(J4-(1-EXP(-200/参数配置!O8)))/((1-EXP(-1500/参数配置!O8))-(1-EXP(-200/参数配置!O8))))*100) -> #DIV/0! | N4: {=IF(G4>0,RLD_Label(G4,H4,I4),"")} -> #NAME? | O4: 1 | P4: =IFERROR(INDEX(参数配置!B:B,MATCH(O4,参数配置!A:A,0)),"") -> 平缓推进
B5: 4 | C5: normal | D5: 1 | G5: 640 | H5: 4 | I5: 0 | J5: =IF(G5="","",1-EXP(-G5/参数配置!O9)) -> #DIV/0! | K5: =IF(H5="","",((H5-2)/4)^2) -> 0.25 | L5: =IF(I5="","",1-2^(-I5)) -> 0 | M5: =IF(G5="","",(参数配置!O5*K5+参数配置!O6*(J5-(1-EXP(-200/参数配置!O9)))/((1-EXP(-1500/参数配置!O9))-(1-EXP(-200/参数配置!O9)))+参数配置!O7*(L5/(1-2^(-5)))+参数配置!O8*K5*(J5-(1-EXP(-200/参数配置!O9)))/((1-EXP(-1500/参数配置!O9))-(1-EXP(-200/参数配置!O9))))*100) -> #DIV/0! | N5: {=IF(G5>0,RLD_Label(G5,H5,I5),"")} -> #NAME? | O5: 1 | P5: =IFERROR(INDEX(参数配置!B:B,MATCH(O5,参数配置!A:A,0)),"") -> 平缓推进
B6: 5 | C6: normal | D6: 1 | E6: 大方块 | H6: =IF(ISBLANK('1-200关设定'!W6),"",'1-200关设定'!W6) -> 3 | I6: =IF(ISBLANK('1-200关设定'!V6),"",'1-200关设定'!V6) -> 1 | J6: =IF(G6="","",1-EXP(-G6/参数配置!O10)) | K6: =IF(H6="","",((H6-2)/4)^2) -> 0.0625 | L6: =IF(I6="","",1-2^(-I6)) -> 0.5 | M6: =IF(G6="","",(参数配置!O6*K6+参数配置!O7*(J6-(1-EXP(-200/参数配置!O10)))/((1-EXP(-1500/参数配置!O10))-(1-EXP(-200/参数配置!O10)))+参数配置!O8*(L6/(1-2^(-5)))+参数配置!O9*K6*(J6-(1-EXP(-200/参数配置!O10)))/((1-EXP(-1500/参数配置!O10))-(1-EXP(-200/参数配置!O10))))*100) | N6: {=IF(G6>0,RLD_Label(G6,H6,I6),"")} | O6: 1 | P6: =IFERROR(INDEX(参数配置!B:B,MATCH(O6,参数配置!A:A,0)),"") -> 平缓推进
B7: 6 | C7: normal | D7: 0.9 | H7: =IF(ISBLANK('1-200关设定'!W7),"",'1-200关设定'!W7) -> 4 | I7: =IF(ISBLANK('1-200关设定'!V7),"",'1-200关设定'!V7) -> 1 | J7: =IF(G7="","",1-EXP(-G7/参数配置!O11)) | K7: =IF(H7="","",((H7-2)/4)^2) -> 0.25 | L7: =IF(I7="","",1-2^(-I7)) -> 0.5 | M7: =IF(G7="","",(参数配置!O7*K7+参数配置!O8*(J7-(1-EXP(-200/参数配置!O11)))/((1-EXP(-1500/参数配置!O11))-(1-EXP(-200/参数配置!O11)))+参数配置!O9*(L7/(1-2^(-5)))+参数配置!O10*K7*(J7-(1-EXP(-200/参数配置!O11)))/((1-EXP(-1500/参数配置!O11))-(1-EXP(-200/参数配置!O11))))*100) | N7: {=IF(G7>0,RLD_Label(G7,H7,I7),"")} | O7: 1 | P7: =IFERROR(INDEX(参数配置!B:B,MATCH(O7,参数配置!A:A,0)),"") -> 平缓推进
B8: 7 | C8: normal | D8: 1 | E8: 问号炮台 | H8: =IF(ISBLANK('1-200关设定'!W8),"",'1-200关设定'!W8) -> 3 | I8: =IF(ISBLANK('1-200关设定'!V8),"",'1-200关设定'!V8) -> 1 | J8: =IF(G8="","",1-EXP(-G8/参数配置!O12)) | K8: =IF(H8="","",((H8-2)/4)^2) -> 0.0625 | L8: =IF(I8="","",1-2^(-I8)) -> 0.5 | M8: =IF(G8="","",(参数配置!O8*K8+参数配置!O9*(J8-(1-EXP(-200/参数配置!O12)))/((1-EXP(-1500/参数配置!O12))-(1-EXP(-200/参数配置!O12)))+参数配置!O10*(L8/(1-2^(-5)))+参数配置!O11*K8*(J8-(1-EXP(-200/参数配置!O12)))/((1-EXP(-1500/参数配置!O12))-(1-EXP(-200/参数配置!O12))))*100) | N8: {=IF(G8>0,RLD_Label(G8,H8,I8),"")} | O8: 1 | P8: =IFERROR(INDEX(参数配置!B:B,MATCH(O8,参数配置!A:A,0)),"") -> 平缓推进
B9: 8 | C9: normal | D9: 0.9 | H9: =IF(ISBLANK('1-200关设定'!W9),"",'1-200关设定'!W9) -> 4 | I9: =IF(ISBLANK('1-200关设定'!V9),"",'1-200关设定'!V9) -> 1 | J9: =IF(G9="","",1-EXP(-G9/参数配置!O13)) | K9: =IF(H9="","",((H9-2)/4)^2) -> 0.25 | L9: =IF(I9="","",1-2^(-I9)) -> 0.5 | M9: =IF(G9="","",(参数配置!O9*K9+参数配置!O10*(J9-(1-EXP(-200/参数配置!O13)))/((1-EXP(-1500/参数配置!O13))-(1-EXP(-200/参数配置!O13)))+参数配置!O11*(L9/(1-2^(-5)))+参数配置!O12*K9*(J9-(1-EXP(-200/参数配置!O13)))/((1-EXP(-1500/参数配置!O13))-(1-EXP(-200/参数配置!O13))))*100) | N9: {=IF(G9>0,RLD_Label(G9,H9,I9),"")} | O9: 1 | P9: =IFERROR(INDEX(参数配置!B:B,MATCH(O9,参数配置!A:A,0)),"") -> 平缓推进
B10: 9 | C10: normal | D10: 0.9 | H10: =IF(ISBLANK('1-200关设定'!W10),"",'1-200关设定'!W10) -> 4 | I10: =IF(ISBLANK('1-200关设定'!V10),"",'1-200关设定'!V10) -> 2 | J10: =IF(G10="","",1-EXP(-G10/参数配置!O14)) | K10: =IF(H10="","",((H10-2)/4)^2) -> 0.25 | L10: =IF(I10="","",1-2^(-I10)) -> 0.75 | M10: =IF(G10="","",(参数配置!O10*K10+参数配置!O11*(J10-(1-EXP(-200/参数配置!O14)))/((1-EXP(-1500/参数配置!O14))-(1-EXP(-200/参数配置!O14)))+参数配置!O12*(L10/(1-2^(-5)))+参数配置!O13*K10*(J10-(1-EXP(-200/参数配置!O14)))/((1-EXP(-1500/参数配置!O14))-(1-EXP(-200/参数配置!O14))))*100) | N10: {=IF(G10>0,RLD_Label(G10,H10,I10),"")} | O10: 1 | P10: =IFERROR(INDEX(参数配置!B:B,MATCH(O10,参数配置!A:A,0)),"") -> 平缓推进
B11: 10 | C11: normal | D11: 1 | E11: 三角炮台 | H11: =IF(ISBLANK('1-200关设定'!W11),"",'1-200关设定'!W11) -> 3 | I11: =IF(ISBLANK('1-200关设定'!V11),"",'1-200关设定'!V11) -> 1 | J11: =IF(G11="","",1-EXP(-G11/参数配置!O15)) | K11: =IF(H11="","",((H11-2)/4)^2) -> 0.0625 | L11: =IF(I11="","",1-2^(-I11)) -> 0.5 | M11: =IF(G11="","",(参数配置!O11*K11+参数配置!O12*(J11-(1-EXP(-200/参数配置!O15)))/((1-EXP(-1500/参数配置!O15))-(1-EXP(-200/参数配置!O15)))+参数配置!O13*(L11/(1-2^(-5)))+参数配置!O14*K11*(J11-(1-EXP(-200/参数配置!O15)))/((1-EXP(-1500/参数配置!O15))-(1-EXP(-200/参数配置!O15))))*100) | N11: {=IF(G11>0,RLD_Label(G11,H11,I11),"")} | O11: 1 | P11: =IFERROR(INDEX(参数配置!B:B,MATCH(O11,参数配置!A:A,0)),"") -> 平缓推进
B12: 11 | C12: normal | D12: 0.9 | H12: =IF(ISBLANK('1-200关设定'!W12),"",'1-200关设定'!W12) -> 4 | I12: =IF(ISBLANK('1-200关设定'!V12),"",'1-200关设定'!V12) -> 2 | J12: =IF(G12="","",1-EXP(-G12/参数配置!O16)) | K12: =IF(H12="","",((H12-2)/4)^2) -> 0.25 | L12: =IF(I12="","",1-2^(-I12)) -> 0.75 | M12: =IF(G12="","",(参数配置!O12*K12+参数配置!O13*(J12-(1-EXP(-200/参数配置!O16)))/((1-EXP(-1500/参数配置!O16))-(1-EXP(-200/参数配置!O16)))+参数配置!O14*(L12/(1-2^(-5)))+参数配置!O15*K12*(J12-(1-EXP(-200/参数配置!O16)))/((1-EXP(-1500/参数配置!O16))-(1-EXP(-200/参数配置!O16))))*100) | N12: {=IF(G12>0,RLD_Label(G12,H12,I12),"")} | O12: 1 | P12: =IFERROR(INDEX(参数配置!B:B,MATCH(O12,参数配置!A:A,0)),"") -> 平缓推进
B13: 12 | C13: normal | D13: 0.9 | H13: =IF(ISBLANK('1-200关设定'!W13),"",'1-200关设定'!W13) -> 4 | I13: =IF(ISBLANK('1-200关设定'!V13),"",'1-200关设定'!V13) -> 2 | J13: =IF(G13="","",1-EXP(-G13/参数配置!O17)) | K13: =IF(H13="","",((H13-2)/4)^2) -> 0.25 | L13: =IF(I13="","",1-2^(-I13)) -> 0.75 | M13: =IF(G13="","",(参数配置!O13*K13+参数配置!O14*(J13-(1-EXP(-200/参数配置!O17)))/((1-EXP(-1500/参数配置!O17))-(1-EXP(-200/参数配置!O17)))+参数配置!O15*(L13/(1-2^(-5)))+参数配置!O16*K13*(J13-(1-EXP(-200/参数配置!O17)))/((1-EXP(-1500/参数配置!O17))-(1-EXP(-200/参数配置!O17))))*100) | N13: {=IF(G13>0,RLD_Label(G13,H13,I13),"")} | O13: 1 | P13: =IFERROR(INDEX(参数配置!B:B,MATCH(O13,参数配置!A:A,0)),"") -> 平缓推进
B14: 13 | C14: normal | D14: 0.9 | E14: 磁铁道具指引 | H14: =IF(ISBLANK('1-200关设定'!W14),"",'1-200关设定'!W14) -> 5 | I14: =IF(ISBLANK('1-200关设定'!V14),"",'1-200关设定'!V14) -> 0 | J14: =IF(G14="","",1-EXP(-G14/参数配置!O18)) | K14: =IF(H14="","",((H14-2)/4)^2) -> 0.5625 | L14: =IF(I14="","",1-2^(-I14)) -> 0 | M14: =IF(G14="","",(参数配置!O14*K14+参数配置!O15*(J14-(1-EXP(-200/参数配置!O18)))/((1-EXP(-1500/参数配置!O18))-(1-EXP(-200/参数配置!O18)))+参数配置!O16*(L14/(1-2^(-5)))+参数配置!O17*K14*(J14-(1-EXP(-200/参数配置!O18)))/((1-EXP(-1500/参数配置!O18))-(1-EXP(-200/参数配置!O18))))*100) | N14: {=IF(G14>0,RLD_Label(G14,H14,I14),"")} | O14: 1 | P14: =IFERROR(INDEX(参数配置!B:B,MATCH(O14,参数配置!A:A,0)),"") -> 平缓推进
B15: 14 | C15: hard | D15: 0.7 | H15: =IF(ISBLANK('1-200关设定'!W15),"",'1-200关设定'!W15) -> 4 | I15: =IF(ISBLANK('1-200关设定'!V15),"",'1-200关设定'!V15) -> 3 | J15: =IF(G15="","",1-EXP(-G15/参数配置!O19)) | K15: =IF(H15="","",((H15-2)/4)^2) -> 0.25 | L15: =IF(I15="","",1-2^(-I15)) -> 0.875 | M15: =IF(G15="","",(参数配置!O15*K15+参数配置!O16*(J15-(1-EXP(-200/参数配置!O19)))/((1-EXP(-1500/参数配置!O19))-(1-EXP(-200/参数配置!O19)))+参数配置!O17*(L15/(1-2^(-5)))+参数配置!O18*K15*(J15-(1-EXP(-200/参数配置!O19)))/((1-EXP(-1500/参数配置!O19))-(1-EXP(-200/参数配置!O19))))*100) | N15: {=IF(G15>0,RLD_Label(G15,H15,I15),"")} | O15: 1 | P15: =IFERROR(INDEX(参数配置!B:B,MATCH(O15,参数配置!A:A,0)),"") -> 平缓推进
B16: 15 | C16: normal | D16: 0.85 | F16: 开始：新手签到+每日签到 | H16: =IF(ISBLANK('1-200关设定'!W16),"",'1-200关设定'!W16) -> 4 | I16: =IF(ISBLANK('1-200关设定'!V16),"",'1-200关设定'!V16) -> 1 | J16: =IF(G16="","",1-EXP(-G16/参数配置!O20)) | K16: =IF(H16="","",((H16-2)/4)^2) -> 0.25 | L16: =IF(I16="","",1-2^(-I16)) -> 0.5 | M16: =IF(G16="","",(参数配置!O16*K16+参数配置!O17*(J16-(1-EXP(-200/参数配置!O20)))/((1-EXP(-1500/参数配置!O20))-(1-EXP(-200/参数配置!O20)))+参数配置!O18*(L16/(1-2^(-5)))+参数配置!O19*K16*(J16-(1-EXP(-200/参数配置!O20)))/((1-EXP(-1500/参数配置!O20))-(1-EXP(-200/参数配置!O20))))*100) | N16: {=IF(G16>0,RLD_Label(G16,H16,I16),"")} | O16: 1 | P16: =IFERROR(INDEX(参数配置!B:B,MATCH(O16,参数配置!A:A,0)),"") -> 平缓推进
B17: 16 | C17: normal | D17: 0.85 | E17: 得分小猪 | H17: =IF(ISBLANK('1-200关设定'!W17),"",'1-200关设定'!W17) -> 3 | I17: =IF(ISBLANK('1-200关设定'!V17),"",'1-200关设定'!V17) -> 0 | J17: =IF(G17="","",1-EXP(-G17/参数配置!O21)) | K17: =IF(H17="","",((H17-2)/4)^2) -> 0.0625 | L17: =IF(I17="","",1-2^(-I17)) -> 0 | M17: =IF(G17="","",(参数配置!O17*K17+参数配置!O18*(J17-(1-EXP(-200/参数配置!O21)))/((1-EXP(-1500/参数配置!O21))-(1-EXP(-200/参数配置!O21)))+参数配置!O19*(L17/(1-2^(-5)))+参数配置!O20*K17*(J17-(1-EXP(-200/参数配置!O21)))/((1-EXP(-1500/参数配置!O21))-(1-EXP(-200/参数配置!O21))))*100) | N17: {=IF(G17>0,RLD_Label(G17,H17,I17),"")} | O17: 1 | P17: =IFERROR(INDEX(参数配置!B:B,MATCH(O17,参数配置!A:A,0)),"") -> 平缓推进
B18: 17 | C18: normal | D18: 0.85 | H18: =IF(ISBLANK('1-200关设定'!W18),"",'1-200关设定'!W18) -> 4 | I18: =IF(ISBLANK('1-200关设定'!V18),"",'1-200关设定'!V18) -> 2 | J18: =IF(G18="","",1-EXP(-G18/参数配置!O22)) | K18: =IF(H18="","",((H18-2)/4)^2) -> 0.25 | L18: =IF(I18="","",1-2^(-I18)) -> 0.75 | M18: =IF(G18="","",(参数配置!O18*K18+参数配置!O19*(J18-(1-EXP(-200/参数配置!O22)))/((1-EXP(-1500/参数配置!O22))-(1-EXP(-200/参数配置!O22)))+参数配置!O20*(L18/(1-2^(-5)))+参数配置!O21*K18*(J18-(1-EXP(-200/参数配置!O22)))/((1-EXP(-1500/参数配置!O22))-(1-EXP(-200/参数配置!O22))))*100) | N18: {=IF(G18>0,RLD_Label(G18,H18,I18),"")} | O18: 1 | P18: =IFERROR(INDEX(参数配置!B:B,MATCH(O18,参数配置!A:A,0)),"") -> 平缓推进
B19: 18 | C19: normal | D19: 0.85 | E19: 魔法棒道具指引 | H19: =IF(ISBLANK('1-200关设定'!W19),"",'1-200关设定'!W19) -> 5 | I19: =IF(ISBLANK('1-200关设定'!V19),"",'1-200关设定'!V19) -> 2 | J19: =IF(G19="","",1-EXP(-G19/参数配置!O23)) | K19: =IF(H19="","",((H19-2)/4)^2) -> 0.5625 | L19: =IF(I19="","",1-2^(-I19)) -> 0.75 | M19: =IF(G19="","",(参数配置!O19*K19+参数配置!O20*(J19-(1-EXP(-200/参数配置!O23)))/((1-EXP(-1500/参数配置!O23))-(1-EXP(-200/参数配置!O23)))+参数配置!O21*(L19/(1-2^(-5)))+参数配置!O22*K19*(J19-(1-EXP(-200/参数配置!O23)))/((1-EXP(-1500/参数配置!O23))-(1-EXP(-200/参数配置!O23))))*100) | N19: {=IF(G19>0,RLD_Label(G19,H19,I19),"")} | O19: 1 | P19: =IFERROR(INDEX(参数配置!B:B,MATCH(O19,参数配置!A:A,0)),"") -> 平缓推进
B20: 19 | C20: hard | D20: 0.6 | F20: 结算：双倍金币出现，fail offer | H20: =IF(ISBLANK('1-200关设定'!W20),"",'1-200关设定'!W20) -> 5 | I20: =IF(ISBLANK('1-200关设定'!V20),"",'1-200关设定'!V20) -> 1 | J20: =IF(G20="","",1-EXP(-G20/参数配置!O24)) | K20: =IF(H20="","",((H20-2)/4)^2) -> 0.5625 | L20: =IF(I20="","",1-2^(-I20)) -> 0.5 | M20: =IF(G20="","",(参数配置!O20*K20+参数配置!O21*(J20-(1-EXP(-200/参数配置!O24)))/((1-EXP(-1500/参数配置!O24))-(1-EXP(-200/参数配置!O24)))+参数配置!O22*(L20/(1-2^(-5)))+参数配置!O23*K20*(J20-(1-EXP(-200/参数配置!O24)))/((1-EXP(-1500/参数配置!O24))-(1-EXP(-200/参数配置!O24))))*100) | N20: {=IF(G20>0,RLD_Label(G20,H20,I20),"")} | O20: 2 | P20: =IFERROR(INDEX(参数配置!B:B,MATCH(O20,参数配置!A:A,0)),"") -> 波动前进
B21: 20 | C21: superhard | D21: 0.4 | H21: =IF(ISBLANK('1-200关设定'!W21),"",'1-200关设定'!W21) -> 4 | I21: =IF(ISBLANK('1-200关设定'!V21),"",'1-200关设定'!V21) -> 3 | J21: =IF(G21="","",1-EXP(-G21/参数配置!O25)) | K21: =IF(H21="","",((H21-2)/4)^2) -> 0.25 | L21: =IF(I21="","",1-2^(-I21)) -> 0.875 | M21: =IF(G21="","",(参数配置!O21*K21+参数配置!O22*(J21-(1-EXP(-200/参数配置!O25)))/((1-EXP(-1500/参数配置!O25))-(1-EXP(-200/参数配置!O25)))+参数配置!O23*(L21/(1-2^(-5)))+参数配置!O24*K21*(J21-(1-EXP(-200/参数配置!O25)))/((1-EXP(-1500/参数配置!O25))-(1-EXP(-200/参数配置!O25))))*100) | N21: {=IF(G21>0,RLD_Label(G21,H21,I21),"")} | O21: 3 | P21: =IFERROR(INDEX(参数配置!B:B,MATCH(O21,参数配置!A:A,0)),"") -> 阶梯上升
A22: 相连炮台 | B22: 21 | C22: normal | D22: 1 | E22: 相连炮台 | H22: =IF(ISBLANK('1-200关设定'!W22),"",'1-200关设定'!W22) -> 3 | I22: =IF(ISBLANK('1-200关设定'!V22),"",'1-200关设定'!V22) -> 1 | J22: =IF(G22="","",1-EXP(-G22/参数配置!O26)) | K22: =IF(H22="","",((H22-2)/4)^2) -> 0.0625 | L22: =IF(I22="","",1-2^(-I22)) -> 0.5 | M22: =IF(G22="","",(参数配置!O22*K22+参数配置!O23*(J22-(1-EXP(-200/参数配置!O26)))/((1-EXP(-1500/参数配置!O26))-(1-EXP(-200/参数配置!O26)))+参数配置!O24*(L22/(1-2^(-5)))+参数配置!O25*K22*(J22-(1-EXP(-200/参数配置!O26)))/((1-EXP(-1500/参数配置!O26))-(1-EXP(-200/参数配置!O26))))*100) | N22: {=IF(G22>0,RLD_Label(G22,H22,I22),"")} | O22: 1 | P22: =IFERROR(INDEX(参数配置!B:B,MATCH(O22,参数配置!A:A,0)),"") -> 平缓推进
B23: 22 | C23: normal | D23: 0.85 | H23: =IF(ISBLANK('1-200关设定'!W23),"",'1-200关设定'!W23) -> 4 | I23: =IF(ISBLANK('1-200关设定'!V23),"",'1-200关设定'!V23) -> 1 | J23: =IF(G23="","",1-EXP(-G23/参数配置!O27)) | K23: =IF(H23="","",((H23-2)/4)^2) -> 0.25 | L23: =IF(I23="","",1-2^(-I23)) -> 0.5 | M23: =IF(G23="","",(参数配置!O23*K23+参数配置!O24*(J23-(1-EXP(-200/参数配置!O27)))/((1-EXP(-1500/参数配置!O27))-(1-EXP(-200/参数配置!O27)))+参数配置!O25*(L23/(1-2^(-5)))+参数配置!O26*K23*(J23-(1-EXP(-200/参数配置!O27)))/((1-EXP(-1500/参数配置!O27))-(1-EXP(-200/参数配置!O27))))*100) | N23: {=IF(G23>0,RLD_Label(G23,H23,I23),"")} | O23: 1 | P23: =IFERROR(INDEX(参数配置!B:B,MATCH(O23,参数配置!A:A,0)),"") -> 平缓推进
B24: 23 | C24: normal | D24: 0.85 | E24: 锤子道具指引 | H24: =IF(ISBLANK('1-200关设定'!W24),"",'1-200关设定'!W24) -> 4 | I24: =IF(ISBLANK('1-200关设定'!V24),"",'1-200关设定'!V24) -> 1 | J24: =IF(G24="","",1-EXP(-G24/参数配置!O28)) | K24: =IF(H24="","",((H24-2)/4)^2) -> 0.25 | L24: =IF(I24="","",1-2^(-I24)) -> 0.5 | M24: =IF(G24="","",(参数配置!O24*K24+参数配置!O25*(J24-(1-EXP(-200/参数配置!O28)))/((1-EXP(-1500/参数配置!O28))-(1-EXP(-200/参数配置!O28)))+参数配置!O26*(L24/(1-2^(-5)))+参数配置!O27*K24*(J24-(1-EXP(-200/参数配置!O28)))/((1-EXP(-1500/参数配置!O28))-(1-EXP(-200/参数配置!O28))))*100) | N24: {=IF(G24>0,RLD_Label(G24,H24,I24),"")} | O24: 2 | P24: =IFERROR(INDEX(参数配置!B:B,MATCH(O24,参数配置!A:A,0)),"") -> 波动前进
B25: 24 | C25: hard | D25: 0.6 | F25: 结算：强制出现广告+免广告系统推送+商店上架免广告pass | H25: =IF(ISBLANK('1-200关设定'!W25),"",'1-200关设定'!W25) -> 5 | I25: =IF(ISBLANK('1-200关设定'!V25),"",'1-200关设定'!V25) -> 3 | J25: =IF(G25="","",1-EXP(-G25/参数配置!O29)) | K25: =IF(H25="","",((H25-2)/4)^2) -> 0.5625 | L25: =IF(I25="","",1-2^(-I25)) -> 0.875 | M25: =IF(G25="","",(参数配置!O25*K25+参数配置!O26*(J25-(1-EXP(-200/参数配置!O29)))/((1-EXP(-1500/参数配置!O29))-(1-EXP(-200/参数配置!O29)))+参数配置!O27*(L25/(1-2^(-5)))+参数配置!O28*K25*(J25-(1-EXP(-200/参数配置!O29)))/((1-EXP(-1500/参数配置!O29))-(1-EXP(-200/参数配置!O29))))*100) | N25: {=IF(G25>0,RLD_Label(G25,H25,I25),"")} | O25: 2 | P25: =IFERROR(INDEX(参数配置!B:B,MATCH(O25,参数配置!A:A,0)),"") -> 波动前进
B26: 25 | C26: normal | D26: 0.85 | F26: 开始：任务 | H26: =IF(ISBLANK('1-200关设定'!W26),"",'1-200关设定'!W26) -> 3 | I26: =IF(ISBLANK('1-200关设定'!V26),"",'1-200关设定'!V26) -> 2 | J26: =IF(G26="","",1-EXP(-G26/参数配置!O30)) | K26: =IF(H26="","",((H26-2)/4)^2) -> 0.0625 | L26: =IF(I26="","",1-2^(-I26)) -> 0.75 | M26: =IF(G26="","",(参数配置!O26*K26+参数配置!O27*(J26-(1-EXP(-200/参数配置!O30)))/((1-EXP(-1500/参数配置!O30))-(1-EXP(-200/参数配置!O30)))+参数配置!O28*(L26/(1-2^(-5)))+参数配置!O29*K26*(J26-(1-EXP(-200/参数配置!O30)))/((1-EXP(-1500/参数配置!O30))-(1-EXP(-200/参数配置!O30))))*100) | N26: {=IF(G26>0,RLD_Label(G26,H26,I26),"")} | O26: 1 | P26: =IFERROR(INDEX(参数配置!B:B,MATCH(O26,参数配置!A:A,0)),"") -> 平缓推进
B27: 26 | C27: normal | D27: 0.85 | E27: 回溯道具指引 | H27: =IF(ISBLANK('1-200关设定'!W27),"",'1-200关设定'!W27) -> 4 | I27: =IF(ISBLANK('1-200关设定'!V27),"",'1-200关设定'!V27) -> 2 | J27: =IF(G27="","",1-EXP(-G27/参数配置!O31)) | K27: =IF(H27="","",((H27-2)/4)^2) -> 0.25 | L27: =IF(I27="","",1-2^(-I27)) -> 0.75 | M27: =IF(G27="","",(参数配置!O27*K27+参数配置!O28*(J27-(1-EXP(-200/参数配置!O31)))/((1-EXP(-1500/参数配置!O31))-(1-EXP(-200/参数配置!O31)))+参数配置!O29*(L27/(1-2^(-5)))+参数配置!O30*K27*(J27-(1-EXP(-200/参数配置!O31)))/((1-EXP(-1500/参数配置!O31))-(1-EXP(-200/参数配置!O31))))*100) | N27: {=IF(G27>0,RLD_Label(G27,H27,I27),"")} | O27: 1 | P27: =IFERROR(INDEX(参数配置!B:B,MATCH(O27,参数配置!A:A,0)),"") -> 平缓推进
B28: 27 | C28: hard | D28: 0.6 | H28: =IF(ISBLANK('1-200关设定'!W28),"",'1-200关设定'!W28) -> 4 | I28: =IF(ISBLANK('1-200关设定'!V28),"",'1-200关设定'!V28) -> 4 | J28: =IF(G28="","",1-EXP(-G28/参数配置!O32)) | K28: =IF(H28="","",((H28-2)/4)^2) -> 0.25 | L28: =IF(I28="","",1-2^(-I28)) -> 0.9375 | M28: =IF(G28="","",(参数配置!O28*K28+参数配置!O29*(J28-(1-EXP(-200/参数配置!O32)))/((1-EXP(-1500/参数配置!O32))-(1-EXP(-200/参数配置!O32)))+参数配置!O30*(L28/(1-2^(-5)))+参数配置!O31*K28*(J28-(1-EXP(-200/参数配置!O32)))/((1-EXP(-1500/参数配置!O32))-(1-EXP(-200/参数配置!O32))))*100) | N28: {=IF(G28>0,RLD_Label(G28,H28,I28),"")} | O28: 2 | P28: =IFERROR(INDEX(参数配置!B:B,MATCH(O28,参数配置!A:A,0)),"") -> 波动前进
B29: 28 | C29: normal | D29: 0.85 | H29: =IF(ISBLANK('1-200关设定'!W29),"",'1-200关设定'!W29) -> 3 | I29: =IF(ISBLANK('1-200关设定'!V29),"",'1-200关设定'!V29) -> 2 | J29: =IF(G29="","",1-EXP(-G29/参数配置!O33)) | K29: =IF(H29="","",((H29-2)/4)^2) -> 0.0625 | L29: =IF(I29="","",1-2^(-I29)) -> 0.75 | M29: =IF(G29="","",(参数配置!O29*K29+参数配置!O30*(J29-(1-EXP(-200/参数配置!O33)))/((1-EXP(-1500/参数配置!O33))-(1-EXP(-200/参数配置!O33)))+参数配置!O31*(L29/(1-2^(-5)))+参数配置!O32*K29*(J29-(1-EXP(-200/参数配置!O33)))/((1-EXP(-1500/参数配置!O33))-(1-EXP(-200/参数配置!O33))))*100) | N29: {=IF(G29>0,RLD_Label(G29,H29,I29),"")} | O29: 1 | P29: =IFERROR(INDEX(参数配置!B:B,MATCH(O29,参数配置!A:A,0)),"") -> 平缓推进
B30: 29 | C30: normal | D30: 0.85 | H30: =IF(ISBLANK('1-200关设定'!W30),"",'1-200关设定'!W30) -> 4 | I30: =IF(ISBLANK('1-200关设定'!V30),"",'1-200关设定'!V30) -> 2 | J30: =IF(G30="","",1-EXP(-G30/参数配置!O34)) | K30: =IF(H30="","",((H30-2)/4)^2) -> 0.25 | L30: =IF(I30="","",1-2^(-I30)) -> 0.75 | M30: =IF(G30="","",(参数配置!O30*K30+参数配置!O31*(J30-(1-EXP(-200/参数配置!O34)))/((1-EXP(-1500/参数配置!O34))-(1-EXP(-200/参数配置!O34)))+参数配置!O32*(L30/(1-2^(-5)))+参数配置!O33*K30*(J30-(1-EXP(-200/参数配置!O34)))/((1-EXP(-1500/参数配置!O34))-(1-EXP(-200/参数配置!O34))))*100) | N30: {=IF(G30>0,RLD_Label(G30,H30,I30),"")} | O30: 1 | P30: =IFERROR(INDEX(参数配置!B:B,MATCH(O30,参数配置!A:A,0)),"") -> 平缓推进
B31: 30 | C31: superhard | D31: 0.4 | H31: =IF(ISBLANK('1-200关设定'!W31),"",'1-200关设定'!W31) -> 4 | I31: =IF(ISBLANK('1-200关设定'!V31),"",'1-200关设定'!V31) -> 2 | J31: =IF(G31="","",1-EXP(-G31/参数配置!O35)) | K31: =IF(H31="","",((H31-2)/4)^2) -> 0.25 | L31: =IF(I31="","",1-2^(-I31)) -> 0.75 | M31: =IF(G31="","",(参数配置!O31*K31+参数配置!O32*(J31-(1-EXP(-200/参数配置!O35)))/((1-EXP(-1500/参数配置!O35))-(1-EXP(-200/参数配置!O35)))+参数配置!O33*(L31/(1-2^(-5)))+参数配置!O34*K31*(J31-(1-EXP(-200/参数配置!O35)))/((1-EXP(-1500/参数配置!O35))-(1-EXP(-200/参数配置!O35))))*100) | N31: {=IF(G31>0,RLD_Label(G31,H31,I31),"")} | O31: 3 | P31: =IFERROR(INDEX(参数配置!B:B,MATCH(O31,参数配置!A:A,0)),"") -> 阶梯上升
B32: 31 | C32: normal | D32: 0.85 | H32: =IF(ISBLANK('1-200关设定'!W32),"",'1-200关设定'!W32) -> 4 | I32: =IF(ISBLANK('1-200关设定'!V32),"",'1-200关设定'!V32) -> 2 | J32: =IF(G32="","",1-EXP(-G32/参数配置!O36)) | K32: =IF(H32="","",((H32-2)/4)^2) -> 0.25 | L32: =IF(I32="","",1-2^(-I32)) -> 0.75 | M32: =IF(G32="","",(参数配置!O32*K32+参数配置!O33*(J32-(1-EXP(-200/参数配置!O36)))/((1-EXP(-1500/参数配置!O36))-(1-EXP(-200/参数配置!O36)))+参数配置!O34*(L32/(1-2^(-5)))+参数配置!O35*K32*(J32-(1-EXP(-200/参数配置!O36)))/((1-EXP(-1500/参数配置!O36))-(1-EXP(-200/参数配置!O36))))*100) | N32: {=IF(G32>0,RLD_Label(G32,H32,I32),"")} | O32: 1 | P32: =IFERROR(INDEX(参数配置!B:B,MATCH(O32,参数配置!A:A,0)),"") -> 平缓推进
B33: 32 | C33: normal | D33: 0.85 | H33: =IF(ISBLANK('1-200关设定'!W33),"",'1-200关设定'!W33) -> 3 | I33: =IF(ISBLANK('1-200关设定'!V33),"",'1-200关设定'!V33) -> 1 | J33: =IF(G33="","",1-EXP(-G33/参数配置!O37)) | K33: =IF(H33="","",((H33-2)/4)^2) -> 0.0625 | L33: =IF(I33="","",1-2^(-I33)) -> 0.5 | M33: =IF(G33="","",(参数配置!O33*K33+参数配置!O34*(J33-(1-EXP(-200/参数配置!O37)))/((1-EXP(-1500/参数配置!O37))-(1-EXP(-200/参数配置!O37)))+参数配置!O35*(L33/(1-2^(-5)))+参数配置!O36*K33*(J33-(1-EXP(-200/参数配置!O37)))/((1-EXP(-1500/参数配置!O37))-(1-EXP(-200/参数配置!O37))))*100) | N33: {=IF(G33>0,RLD_Label(G33,H33,I33),"")} | O33: 1 | P33: =IFERROR(INDEX(参数配置!B:B,MATCH(O33,参数配置!A:A,0)),"") -> 平缓推进
B34: 33 | C34: normal | D34: 0.85 | H34: =IF(ISBLANK('1-200关设定'!W34),"",'1-200关设定'!W34) -> 4 | I34: =IF(ISBLANK('1-200关设定'!V34),"",'1-200关设定'!V34) -> 2 | J34: =IF(G34="","",1-EXP(-G34/参数配置!O38)) | K34: =IF(H34="","",((H34-2)/4)^2) -> 0.25 | L34: =IF(I34="","",1-2^(-I34)) -> 0.75 | M34: =IF(G34="","",(参数配置!O34*K34+参数配置!O35*(J34-(1-EXP(-200/参数配置!O38)))/((1-EXP(-1500/参数配置!O38))-(1-EXP(-200/参数配置!O38)))+参数配置!O36*(L34/(1-2^(-5)))+参数配置!O37*K34*(J34-(1-EXP(-200/参数配置!O38)))/((1-EXP(-1500/参数配置!O38))-(1-EXP(-200/参数配置!O38))))*100) | N34: {=IF(G34>0,RLD_Label(G34,H34,I34),"")} | O34: 2 | P34: =IFERROR(INDEX(参数配置!B:B,MATCH(O34,参数配置!A:A,0)),"") -> 波动前进
B35: 34 | C35: normal | D35: 0.85 | E35: 门 | H35: =IF(ISBLANK('1-200关设定'!W35),"",'1-200关设定'!W35) -> 3 | I35: =IF(ISBLANK('1-200关设定'!V35),"",'1-200关设定'!V35) -> 1 | J35: =IF(G35="","",1-EXP(-G35/参数配置!O39)) | K35: =IF(H35="","",((H35-2)/4)^2) -> 0.0625 | L35: =IF(I35="","",1-2^(-I35)) -> 0.5 | M35: =IF(G35="","",(参数配置!O35*K35+参数配置!O36*(J35-(1-EXP(-200/参数配置!O39)))/((1-EXP(-1500/参数配置!O39))-(1-EXP(-200/参数配置!O39)))+参数配置!O37*(L35/(1-2^(-5)))+参数配置!O38*K35*(J35-(1-EXP(-200/参数配置!O39)))/((1-EXP(-1500/参数配置!O39))-(1-EXP(-200/参数配置!O39))))*100) | N35: {=IF(G35>0,RLD_Label(G35,H35,I35),"")} | O35: 1 | P35: =IFERROR(INDEX(参数配置!B:B,MATCH(O35,参数配置!A:A,0)),"") -> 平缓推进
B36: 35 | C36: normal | D36: 0.85 | F36: 开始：通行证+商店上架通行证 | H36: =IF(ISBLANK('1-200关设定'!W36),"",'1-200关设定'!W36) -> 4 | I36: =IF(ISBLANK('1-200关设定'!V36),"",'1-200关设定'!V36) -> 2 | J36: =IF(G36="","",1-EXP(-G36/参数配置!O40)) | K36: =IF(H36="","",((H36-2)/4)^2) -> 0.25 | L36: =IF(I36="","",1-2^(-I36)) -> 0.75 | M36: =IF(G36="","",(参数配置!O36*K36+参数配置!O37*(J36-(1-EXP(-200/参数配置!O40)))/((1-EXP(-1500/参数配置!O40))-(1-EXP(-200/参数配置!O40)))+参数配置!O38*(L36/(1-2^(-5)))+参数配置!O39*K36*(J36-(1-EXP(-200/参数配置!O40)))/((1-EXP(-1500/参数配置!O40))-(1-EXP(-200/参数配置!O40))))*100) | N36: {=IF(G36>0,RLD_Label(G36,H36,I36),"")} | O36: 1 | P36: =IFERROR(INDEX(参数配置!B:B,MATCH(O36,参数配置!A:A,0)),"") -> 平缓推进
B37: 36 | C37: normal | D37: 0.85 | H37: =IF(ISBLANK('1-200关设定'!W37),"",'1-200关设定'!W37) -> 3 | I37: =IF(ISBLANK('1-200关设定'!V37),"",'1-200关设定'!V37) -> 2 | J37: =IF(G37="","",1-EXP(-G37/参数配置!O41)) | K37: =IF(H37="","",((H37-2)/4)^2) -> 0.0625 | L37: =IF(I37="","",1-2^(-I37)) -> 0.75 | M37: =IF(G37="","",(参数配置!O37*K37+参数配置!O38*(J37-(1-EXP(-200/参数配置!O41)))/((1-EXP(-1500/参数配置!O41))-(1-EXP(-200/参数配置!O41)))+参数配置!O39*(L37/(1-2^(-5)))+参数配置!O40*K37*(J37-(1-EXP(-200/参数配置!O41)))/((1-EXP(-1500/参数配置!O41))-(1-EXP(-200/参数配置!O41))))*100) | N37: {=IF(G37>0,RLD_Label(G37,H37,I37),"")} | O37: 2 | P37: =IFERROR(INDEX(参数配置!B:B,MATCH(O37,参数配置!A:A,0)),"") -> 波动前进
B38: 37 | C38: normal | D38: 0.85 | H38: =IF(ISBLANK('1-200关设定'!W38),"",'1-200关设定'!W38) -> 4 | I38: =IF(ISBLANK('1-200关设定'!V38),"",'1-200关设定'!V38) -> 2 | J38: =IF(G38="","",1-EXP(-G38/参数配置!O42)) | K38: =IF(H38="","",((H38-2)/4)^2) -> 0.25 | L38: =IF(I38="","",1-2^(-I38)) -> 0.75 | M38: =IF(G38="","",(参数配置!O38*K38+参数配置!O39*(J38-(1-EXP(-200/参数配置!O42)))/((1-EXP(-1500/参数配置!O42))-(1-EXP(-200/参数配置!O42)))+参数配置!O40*(L38/(1-2^(-5)))+参数配置!O41*K38*(J38-(1-EXP(-200/参数配置!O42)))/((1-EXP(-1500/参数配置!O42))-(1-EXP(-200/参数配置!O42))))*100) | N38: {=IF(G38>0,RLD_Label(G38,H38,I38),"")} | O38: 1 | P38: =IFERROR(INDEX(参数配置!B:B,MATCH(O38,参数配置!A:A,0)),"") -> 平缓推进
B39: 38 | C39: hard | D39: 0.6 | H39: =IF(ISBLANK('1-200关设定'!W39),"",'1-200关设定'!W39) -> 4 | I39: =IF(ISBLANK('1-200关设定'!V39),"",'1-200关设定'!V39) -> 3 | J39: =IF(G39="","",1-EXP(-G39/参数配置!O43)) | K39: =IF(H39="","",((H39-2)/4)^2) -> 0.25 | L39: =IF(I39="","",1-2^(-I39)) -> 0.875 | M39: =IF(G39="","",(参数配置!O39*K39+参数配置!O40*(J39-(1-EXP(-200/参数配置!O43)))/((1-EXP(-1500/参数配置!O43))-(1-EXP(-200/参数配置!O43)))+参数配置!O41*(L39/(1-2^(-5)))+参数配置!O42*K39*(J39-(1-EXP(-200/参数配置!O43)))/((1-EXP(-1500/参数配置!O43))-(1-EXP(-200/参数配置!O43))))*100) | N39: {=IF(G39>0,RLD_Label(G39,H39,I39),"")} | O39: 1 | P39: =IFERROR(INDEX(参数配置!B:B,MATCH(O39,参数配置!A:A,0)),"") -> 平缓推进
B40: 39 | C40: normal | D40: 0.85 | H40: =IF(ISBLANK('1-200关设定'!W40),"",'1-200关设定'!W40) -> 4 | I40: =IF(ISBLANK('1-200关设定'!V40),"",'1-200关设定'!V40) -> 2 | J40: =IF(G40="","",1-EXP(-G40/参数配置!O44)) | K40: =IF(H40="","",((H40-2)/4)^2) -> 0.25 | L40: =IF(I40="","",1-2^(-I40)) -> 0.75 | M40: =IF(G40="","",(参数配置!O40*K40+参数配置!O41*(J40-(1-EXP(-200/参数配置!O44)))/((1-EXP(-1500/参数配置!O44))-(1-EXP(-200/参数配置!O44)))+参数配置!O42*(L40/(1-2^(-5)))+参数配置!O43*K40*(J40-(1-EXP(-200/参数配置!O44)))/((1-EXP(-1500/参数配置!O44))-(1-EXP(-200/参数配置!O44))))*100) | N40: {=IF(G40>0,RLD_Label(G40,H40,I40),"")} | O40: 2 | P40: =IFERROR(INDEX(参数配置!B:B,MATCH(O40,参数配置!A:A,0)),"") -> 波动前进
...

Sheet 参数配置
A1: 死亡分布配置 | M1: RLD参数配置
A2: 编号 | B2: 名称 | C2: 死亡分布 | M2: W_search (颜色搜索): | O2: 0.3
A3: 1 | B3: 平缓推进 | C3: 0.1,0.1,0.1,0.1,0.1,0.1,0.1,0.1,0.1,0.1 | M3: W_endurance (操作耐力): | O3: 0.35
A4: 2 | B4: 波动前进 | C4: 0,0.2,0,0.2,0,0.2,0,0.2,0,0.2 | M4: W_strategy (策略复杂度): | O4: 0.15
A5: 3 | B5: 阶梯上升 | C5: 0,0,0.018,0.042,0.109,0.159,0.213,0.282,0.121,0.056 | M5: W_search×endurance (交互): | O5: 0.2
A6: 4 | B6: 双峰值 | C6: 0,0,0.125,0.25,0.125,0,0.125,0.25,0.125,0 | M6: λ (endurance threshold): | O6: 800
A7: 5 | B7: 起死回生 | C7: 0,0,0.027,0.126,0.31,0.537,0,0,0,0
A8: 6 | B8: 先易后难 | C8: 0,0,0,0,0.025,0.084,0.183,0.52,0.188,0
A9: 7 | B9: 先难后易 | C9: 0,0.176,0.341,0.251,0.141,0.085,0,0,0,0
M11: Quick Reference - Micro-Difficulty Values
M13: F_search(N_c) = ((N_c - 2) / 4)²
M14: N_c (Color Count) | N14: F_search | O14: F_search_norm | P14: Experience
M15: 2 | N15: =((M15-2)/4)^2 -> 0 | O15: =N15 -> 0 | P15: 极简 - Tutorial only
M16: 3 | N16: =((M16-2)/4)^2 -> 0.0625 | O16: =N16 -> 0.0625 | P16: 简单 - Early game
M17: 4 | N17: =((M17-2)/4)^2 -> 0.25 | O17: =N17 -> 0.25 | P17: 标准 - Core gameplay
M18: 5 | N18: =((M18-2)/4)^2 -> 0.5625 | O18: =N18 -> 0.5625 | P18: 困难 - Key difficulty jump!
M19: 6 | N19: =((M19-2)/4)^2 -> 1 | O19: =N19 -> 1 | P19: 极难 - Boss levels only
M22: F_strategy(N_s) = 1 - 2^(-N_s)
M23: N_s (Special Block Types) | N23: F_strategy | O23: F_strategy_norm | P23: Experience
M24: 0 | N24: =1-2^(-M24) -> 0 | O24: =N24/(1-2^(-5)) -> 0 | P24: 纯色消除 - Boring without specials
M25: 1 | N25: =1-2^(-M25) -> 0.5 | O25: =N25/(1-2^(-5)) -> 0.51612903 | P25: 单一机制 - Standard
M26: 2 | N26: =1-2^(-M26) -> 0.75 | O26: =N26/(1-2^(-5)) -> 0.77419355 | P26: 双重机制 - Core gameplay
M27: 3 | N27: =1-2^(-M27) -> 0.875 | O27: =N27/(1-2^(-5)) -> 0.90322581 | P27: 三重机制 - Complex
M28: 4 | N28: =1-2^(-M28) -> 0.9375 | O28: =N28/(1-2^(-5)) -> 0.96774194 | P28: 四重机制 - Very complex
M29: 5 | N29: =1-2^(-M29) -> 0.96875 | O29: =N29/(1-2^(-5)) -> 1 | P29: 五重机制 - Extreme
M32: F_endurance(N_b) = 1 - exp(-N_b / λ)
M33: N_b (Total Blocks) | N33: F_endurance | O33: F_endurance_norm | P33: Experience
M34: 200 | N34: =1-EXP(-M34/O6) -> 0.22119922 | O34: =(N34-(1-EXP(-200/O6)))/((1-EXP(-1500/O6))-(1-EXP(-200/O6))) -> 0 | P34: 极简 - Tutorial
M35: 300 | N35: =1-EXP(-M35/O6) -> 0.31271072 | O35: =(N35-(1-EXP(-200/O6)))/((1-EXP(-1500/O6))-(1-EXP(-200/O6))) -> 0.14631404 | P35: 简单
M36: 400 | N36: =1-EXP(-M36/O6) -> 0.39346934 | O36: =(N36-(1-EXP(-200/O6)))/((1-EXP(-1500/O6))-(1-EXP(-200/O6))) -> 0.27543573 | P36: 入门
M37: 500 | N37: =1-EXP(-M37/O6) -> 0.46473857 | O37: =(N37-(1-EXP(-200/O6)))/((1-EXP(-1500/O6))-(1-EXP(-200/O6))) -> 0.38938522 | P37: 舒适区下限
M38: 600 | N38: =1-EXP(-M38/O6) -> 0.52763345 | O38: =(N38-(1-EXP(-200/O6)))/((1-EXP(-1500/O6))-(1-EXP(-200/O6))) -> 0.48994529 | P38: 舒适区
M39: 700 | N39: =1-EXP(-M39/O6) -> 0.58313798 | O39: =(N39-(1-EXP(-200/O6)))/((1-EXP(-1500/O6))-(1-EXP(-200/O6))) -> 0.57868924 | P39: 舒适区上限
M40: 800 | N40: =1-EXP(-M40/O6) -> 0.63212056 | O40: =(N40-(1-EXP(-200/O6)))/((1-EXP(-1500/O6))-(1-EXP(-200/O6))) -> 0.6570055 | P40: 标准挑战
M41: 900 | N41: =1-EXP(-M41/O6) -> 0.67534753 | O41: =(N41-(1-EXP(-200/O6)))/((1-EXP(-1500/O6))-(1-EXP(-200/O6))) -> 0.72611936 | P41: 有挑战
M42: 1000 | N42: =1-EXP(-M42/O6) -> 0.7134952 | O42: =(N42-(1-EXP(-200/O6)))/((1-EXP(-1500/O6))-(1-EXP(-200/O6))) -> 0.78711213 | P42: 高挑战
M43: 1100 | N43: =1-EXP(-M43/O6) -> 0.7471604 | O43: =(N43-(1-EXP(-200/O6)))/((1-EXP(-1500/O6))-(1-EXP(-200/O6))) -> 0.84093805 | P43: 高疲劳
M44: 1200 | N44: =1-EXP(-M44/O6) -> 0.77686984 | O44: =(N44-(1-EXP(-200/O6)))/((1-EXP(-1500/O6))-(1-EXP(-200/O6))) -> 0.88843927 | P44: 极高疲劳
M45: 1300 | N45: =1-EXP(-M45/O6) -> 0.80308832 | O45: =(N45-(1-EXP(-200/O6)))/((1-EXP(-1500/O6))-(1-EXP(-200/O6))) -> 0.93035894 | P45: 极限
M46: 1400 | N46: =1-EXP(-M46/O6) -> 0.82622606 | O46: =(N46-(1-EXP(-200/O6)))/((1-EXP(-1500/O6))-(1-EXP(-200/O6))) -> 0.96735292 | P46: 超极限 - Avoid!
...

Sheet 公式说明
A1: RLD Difficulty Formula - Complete Reference
B3: COMPLETE FORMULA
A4: Score | B4: =(W_s*F_search_norm+W_e*F_endurance_norm+W_t*F_strategy_norm+W_se*F_search_norm*F_endurance_norm)*100 -> #NAME?
B6: MICRO-DIFFICULTY FUNCTIONS
A7: F_search(N_c) | C7: Visual search difficulty | D7: 2色=0, 3色=0.063, 4色=0.250, 5色=0.562, 6色=1.000
A8: F_endurance(N_b) | B8: =1-EXP(-N_b/λ) -> #NAME? | C8: Endurance/fatigue difficulty | D8: λ=800: 200块=0.22, 800块=0.63, 1500块=0.85
A9: F_strategy(N_s) | B9: =1-2^(-N_s) -> #NAME? | C9: Strategy complexity | D9: 0种=0, 1种=0.50, 2种=0.75, 3种=0.875, 5种=0.969
B11: NORMALIZATION
A12: F_norm | B12: =(F-F_min)/(F_max-F_min) -> #NAME? | C12: Scale to [0, 1] | D12: Ensures equal contribution range
A13: F_search_norm | B13: =F_search (already #REF!) -> #NAME? | C13: Min at N_c=2, Max at N_c=6
A14: F_endurance_norm | B14: =(F-F(200))/(F(1500)-F(200)) -> #NAME? | C14: Min at blocks=200, Max at blocks=1500
A15: F_strategy_norm | B15: =F_strategy/F_strategy(5) -> #NAME? | C15: Min at N_s=0, Max at N_s=5
B17: WEIGHTS
A18: W_search | B18: =0.3 -> 0.3 | C18: Color is the core Blast lever | D18: Probability of same-color match ∝ 1/N_c^4
A19: W_endurance | B19: =0.35 -> 0.35 | C19: Blocks drive fatigue | D19: Largest continuous variable (52 unique values)
A20: W_strategy | B20: =0.15 -> 0.15 | C20: Special blocks add complexity | D20: Important but not core difficulty driver
A21: W_search×endurance | B21: =0.2 -> 0.2 | C21: Interaction: color amplifies block difficulty | D21: RLD key insight: difficulty is multiplicative, not additive
B23: DIFFICULTY LABELS
A24: D0 (Easy) | B24: Score < 35 | C24: Relaxed gameplay
A25: D1 (Medium) | B25: 35 ≤ Score < 55 | C25: Moderate challenge
A26: D2 (Hard) | B26: Score ≥ 55 | C26: High challenge
B28: CALIBRATION (when you have playtest data)
A29: Step 1 | B29: Collect: pass_rate, avg_attempts, churn_rate per level
A30: Step 2 | B30: Define: true_diff = -log(pass_rate) × (1+churn_rate) × avg_attempts
A31: Step 3 | B31: Regress: true_diff ~ F_search + F_endurance + F_strategy + F_search×F_endurance
A32: Step 4 | B32: Use regression coefficients as calibrated weights
A33: Step 5 | B33: Grid search λ ∈ [600,1000] to maximize R²
