Workbook

Sheet LevelTierData
A1: pack | B1: levelName | C1: difficultyLevel | D1: difficultyLabel | E1: tier | F1: isBaseTop | G1: StartDifficulty | H1: LevelDifficultyFactor | I1: ShuffleSplitCount | J1: ShuffleSplitRatios | K1: ShuffleOverflowFactor | L1: runCount | M1: winCount | N1: failCount | O1: winRate | P1: avgQueueEff | Q1: failBucketDistribution
A2: funnel_b | B2: 1 | C2: 0 | D2: normal | E2: 1 | F2: 0 | G2: 18 | H2: 12 | I2: 3 | J2: 1,2,1 | K2: 0.75 | L2: 0 | M2: 0 | N2: 0 | O2: =IF(M3>0,N3/M3,0) -> 0
A3: funnel_b | E3: 2 | F3: 0 | G3: 18 | H3: 12 | I3: 3 | J3: 1,2,1 | K3: 0.75 | L3: 0 | M3: 0 | N3: 0 | O3: =IF(M4>0,N4/M4,0) -> 0
A4: funnel_b | E4: 3 | F4: 0 | G4: 18 | H4: 12 | I4: 3 | J4: 1,2,1 | K4: 0.75 | L4: 0 | M4: 0 | N4: 0 | O4: =IF(M5>0,N5/M5,0) -> 0
A5: funnel_b | E5: 4 | F5: 0 | G5: 18 | H5: 12 | I5: 3 | J5: 1,2,1 | K5: 0.75 | L5: 0 | M5: 0 | N5: 0 | O5: =IF(M6>0,N6/M6,0) -> 0
A6: funnel_b | E6: 5 | F6: 0 | G6: 18 | H6: 12 | I6: 3 | J6: 1,2,1 | K6: 0.75 | L6: 0 | M6: 0 | N6: 0 | O6: =IF(M7>0,N7/M7,0) -> 0
A7: funnel_b | B7: 2 | C7: 0 | D7: normal | E7: 1 | F7: 0 | G7: 18 | H7: 12 | I7: 3 | J7: 1,2,1 | K7: 0.75 | L7: 0 | M7: 0 | N7: 0 | O7: =IF(M9>0,N9/M9,0) -> 0
A8: funnel_b | E8: 2 | F8: 0 | G8: 18 | H8: 12 | I8: 3 | J8: 1,2,1 | K8: 0.75 | L8: 0 | M8: 0 | N8: 0 | O8: =IF(M10>0,N10/M10,0) -> 0
A9: funnel_b | E9: 3 | F9: 0 | G9: 18 | H9: 12 | I9: 3 | J9: 1,2,1 | K9: 0.75 | L9: 0 | M9: 0 | N9: 0 | O9: =IF(M11>0,N11/M11,0) -> 0
A10: funnel_b | E10: 4 | F10: 0 | G10: 18 | H10: 12 | I10: 3 | J10: 1,2,1 | K10: 0.75 | L10: 0 | M10: 0 | N10: 0 | O10: =IF(M12>0,N12/M12,0) -> 0
A11: funnel_b | E11: 5 | F11: 0 | G11: 18 | H11: 12 | I11: 3 | J11: 1,2,1 | K11: 0.75 | L11: 0 | M11: 0 | N11: 0 | O11: =IF(M13>0,N13/M13,0) -> 0
A12: funnel_b | B12: 3 | C12: 0 | D12: normal | E12: 1 | F12: 0 | G12: 18 | H12: 12 | I12: 3 | J12: 1,2,1 | K12: 0.75 | L12: 0 | M12: 0 | N12: 0 | O12: =IF(M15>0,N15/M15,0) -> 0
A13: funnel_b | E13: 2 | F13: 0 | G13: 18 | H13: 12 | I13: 3 | J13: 1,2,1 | K13: 0.75 | L13: 0 | M13: 0 | N13: 0 | O13: =IF(M16>0,N16/M16,0) -> 0
A14: funnel_b | E14: 3 | F14: 0 | G14: 18 | H14: 12 | I14: 3 | J14: 1,2,1 | K14: 0.75 | L14: 0 | M14: 0 | N14: 0 | O14: =IF(M17>0,N17/M17,0) -> 0
A15: funnel_b | E15: 4 | F15: 0 | G15: 18 | H15: 12 | I15: 3 | J15: 1,2,1 | K15: 0.75 | L15: 0 | M15: 0 | N15: 0 | O15: =IF(M18>0,N18/M18,0) -> 0
A16: funnel_b | E16: 5 | F16: 0 | G16: 18 | H16: 12 | I16: 3 | J16: 1,2,1 | K16: 0.75 | L16: 0 | M16: 0 | N16: 0 | O16: =IF(M19>0,N19/M19,0) -> 0
A17: funnel_b | B17: 4 | C17: 0 | D17: normal | E17: 1 | F17: 0 | G17: 18 | H17: 12 | I17: 3 | J17: 1,2,1 | K17: 0.75 | L17: 0 | M17: 0 | N17: 0 | O17: =IF(M21>0,N21/M21,0) -> 0
A18: funnel_b | E18: 2 | F18: 0 | G18: 18 | H18: 12 | I18: 3 | J18: 1,2,1 | K18: 0.75 | L18: 0 | M18: 0 | N18: 0 | O18: =IF(M22>0,N22/M22,0) -> 0
A19: funnel_b | E19: 3 | F19: 0 | G19: 18 | H19: 12 | I19: 3 | J19: 1,2,1 | K19: 0.75 | L19: 0 | M19: 0 | N19: 0 | O19: =IF(M23>0,N23/M23,0) -> 0
A20: funnel_b | E20: 4 | F20: 0 | G20: 18 | H20: 12 | I20: 3 | J20: 1,2,1 | K20: 0.75 | L20: 0 | M20: 0 | N20: 0 | O20: =IF(M24>0,N24/M24,0) -> 0
A21: funnel_b | E21: 5 | F21: 0 | G21: 18 | H21: 12 | I21: 3 | J21: 1,2,1 | K21: 0.75 | L21: 0 | M21: 0 | N21: 0 | O21: =IF(M25>0,N25/M25,0) -> 0
A22: funnel_b | B22: 5 | C22: 0 | D22: normal | E22: 1 | F22: 0 | G22: 18 | H22: 12 | I22: 3 | J22: 1,2,1 | K22: 0.75 | L22: 0 | M22: 0 | N22: 0 | O22: =IF(M27>0,N27/M27,0) -> 0
A23: funnel_b | E23: 2 | F23: 0 | G23: 18 | H23: 12 | I23: 3 | J23: 1,2,1 | K23: 0.75 | L23: 0 | M23: 0 | N23: 0 | O23: =IF(M28>0,N28/M28,0) -> 0
A24: funnel_b | E24: 3 | F24: 0 | G24: 18 | H24: 12 | I24: 3 | J24: 1,2,1 | K24: 0.75 | L24: 0 | M24: 0 | N24: 0 | O24: =IF(M29>0,N29/M29,0) -> 0
A25: funnel_b | E25: 4 | F25: 0 | G25: 18 | H25: 12 | I25: 3 | J25: 1,2,1 | K25: 0.75 | L25: 0 | M25: 0 | N25: 0 | O25: =IF(M30>0,N30/M30,0) -> 0
A26: funnel_b | E26: 5 | F26: 0 | G26: 18 | H26: 12 | I26: 3 | J26: 1,2,1 | K26: 0.75 | L26: 0 | M26: 0 | N26: 0 | O26: =IF(M31>0,N31/M31,0) -> 0
A27: funnel_b | B27: 6 | C27: 0 | D27: normal | E27: 1 | F27: 0 | G27: 19 | H27: 12 | I27: 3 | J27: 1,2,1 | K27: 0.75 | L27: 0 | M27: 0 | N27: 0 | O27: =IF(M33>0,N33/M33,0) -> 0
A28: funnel_b | E28: 2 | F28: 0 | G28: 19 | H28: 12 | I28: 3 | J28: 1,2,1 | K28: 0.75 | L28: 0 | M28: 0 | N28: 0 | O28: =IF(M34>0,N34/M34,0) -> 0
A29: funnel_b | E29: 3 | F29: 0 | G29: 19 | H29: 12 | I29: 3 | J29: 1,2,1 | K29: 0.75 | L29: 0 | M29: 0 | N29: 0 | O29: =IF(M35>0,N35/M35,0) -> 0
A30: funnel_b | E30: 4 | F30: 0 | G30: 19 | H30: 12 | I30: 3 | J30: 1,2,1 | K30: 0.75 | L30: 0 | M30: 0 | N30: 0 | O30: =IF(M36>0,N36/M36,0) -> 0
A31: funnel_b | E31: 5 | F31: 0 | G31: 19 | H31: 12 | I31: 3 | J31: 1,2,1 | K31: 0.75 | L31: 0 | M31: 0 | N31: 0 | O31: =IF(M37>0,N37/M37,0) -> 0
A32: funnel_b | B32: 7 | C32: 0 | D32: normal | E32: 1 | F32: 0 | G32: 13 | H32: 12 | I32: 3 | J32: 1,2,1 | K32: 0.72 | L32: 0 | M32: 0 | N32: 0 | O32: =IF(M39>0,N39/M39,0) -> 0
A33: funnel_b | E33: 2 | F33: 0 | G33: 13 | H33: 12 | I33: 3 | J33: 1,2,1 | K33: 0.72 | L33: 0 | M33: 0 | N33: 0 | O33: =IF(M40>0,N40/M40,0) -> 0
A34: funnel_b | E34: 3 | F34: 0 | G34: 13 | H34: 12 | I34: 3 | J34: 1,2,1 | K34: 0.72 | L34: 0 | M34: 0 | N34: 0 | O34: =IF(M41>0,N41/M41,0) -> 0
A35: funnel_b | E35: 4 | F35: 0 | G35: 13 | H35: 12 | I35: 3 | J35: 1,2,1 | K35: 0.72 | L35: 0 | M35: 0 | N35: 0 | O35: =IF(M42>0,N42/M42,0) -> 0
A36: funnel_b | E36: 5 | F36: 0 | G36: 13 | H36: 12 | I36: 3 | J36: 1,2,1 | K36: 0.72 | L36: 0 | M36: 0 | N36: 0 | O36: =IF(M43>0,N43/M43,0) -> 0
A37: funnel_b | B37: 8 | C37: 0 | D37: normal | E37: 1 | F37: 0 | G37: 7 | H37: 12 | I37: 3 | J37: 1,2,1 | K37: 0.72 | L37: 0 | M37: 0 | N37: 0 | O37: =IF(M45>0,N45/M45,0) -> 0
A38: funnel_b | E38: 2 | F38: 0 | G38: 7 | H38: 12 | I38: 3 | J38: 1,2,1 | K38: 0.72 | L38: 0 | M38: 0 | N38: 0 | O38: =IF(M46>0,N46/M46,0) -> 0
A39: funnel_b | E39: 3 | F39: 0 | G39: 7 | H39: 12 | I39: 3 | J39: 1,2,1 | K39: 0.72 | L39: 0 | M39: 0 | N39: 0 | O39: =IF(M47>0,N47/M47,0) -> 0
A40: funnel_b | E40: 4 | F40: 0 | G40: 7 | H40: 12 | I40: 3 | J40: 1,2,1 | K40: 0.72 | L40: 0 | M40: 0 | N40: 0 | O40: =IF(M48>0,N48/M48,0) -> 0
...

Sheet RunData
A1: pack | B1: levelName | C1: difficultyLevel | D1: difficultyLabel | E1: configGroup | F1: StartDifficulty | G1: LevelDifficultyFactor | H1: ShuffleSplitCount | I1: ShuffleSplitRatios | J1: ShuffleOverflowFactor | K1: failBucketDistribution | L1: winCount | M1: failCount | N1: winRate | O1: avgQueueEff
A2: funnel_b | B2: 1 | C2: 0 | D2: normal | E2: T1 | F2: 18 | G2: 12 | H2: 3 | I2: 1,2,1 | J2: 0.75 | K2: 0,0,0,0,0,0,0,0,0,0 | L2: 100 | M2: 0 | N2: 1
A3: funnel_b | E3: T2 | F3: 18 | G3: 12 | H3: 3 | I3: 1,2,1 | J3: 0.75 | K3: 0,0,0,0,0,0,0,0,0,0 | L3: 100 | M3: 0 | N3: 1
A4: funnel_b | E4: T3 | F4: 18 | G4: 12 | H4: 3 | I4: 1,2,1 | J4: 0.75 | K4: 0,0,0,0,0,0,0,0,0,0 | L4: 100 | M4: 0 | N4: 1
A5: funnel_b | E5: T4 | F5: 18 | G5: 12 | H5: 3 | I5: 1,2,1 | J5: 0.75 | K5: 0,0,0,0,0,0,0,0,0,0 | L5: 100 | M5: 0 | N5: 1
A6: funnel_b | E6: T5 | F6: 18 | G6: 12 | H6: 3 | I6: 1,2,1 | J6: 0.75 | K6: 0,0,0,0,0,0,0,0,0,0 | L6: 100 | M6: 0 | N6: 1
A7: funnel_b | B7: 2 | C7: 0 | D7: normal | E7: T1 | F7: 18 | G7: 12 | H7: 3 | I7: 1,2,1 | J7: 0.75 | K7: 0,0,0,0,0,0,0,0,0,0 | L7: 100 | M7: 0 | N7: 1
A8: funnel_b | E8: T2 | F8: 18 | G8: 12 | H8: 3 | I8: 1,2,1 | J8: 0.75 | K8: 0,0,0,0,0,0,0,0,0,0 | L8: 100 | M8: 0 | N8: 1
A9: funnel_b | E9: T3 | F9: 18 | G9: 12 | H9: 3 | I9: 1,2,1 | J9: 0.75 | K9: 0,0,0,0,0,0,0,0,0,0 | L9: 100 | M9: 0 | N9: 1
A10: funnel_b | E10: T4 | F10: 18 | G10: 12 | H10: 3 | I10: 1,2,1 | J10: 0.75 | K10: 0,0,0,0,0,0,0,0,0,0 | L10: 100 | M10: 0 | N10: 1
A11: funnel_b | E11: T5 | F11: 18 | G11: 12 | H11: 3 | I11: 1,2,1 | J11: 0.75 | K11: 0,0,0,0,0,0,0,0,0,0 | L11: 100 | M11: 0 | N11: 1
A12: funnel_b | B12: 3 | C12: 0 | D12: normal | E12: T1 | F12: 18 | G12: 12 | H12: 3 | I12: 1,2,1 | J12: 0.75 | K12: 0,0,0,0,0,0,0,0,0,0 | L12: 100 | M12: 0 | N12: 1
A13: funnel_b | E13: T2 | F13: 18 | G13: 12 | H13: 3 | I13: 1,2,1 | J13: 0.75 | K13: 0,0,0,0,0,0,0,0,0,0 | L13: 100 | M13: 0 | N13: 1
A14: funnel_b | E14: T3 | F14: 18 | G14: 12 | H14: 3 | I14: 1,2,1 | J14: 0.75 | K14: 0,0,0,0,0,0,0,0,0,0 | L14: 100 | M14: 0 | N14: 1
A15: funnel_b | E15: T4 | F15: 18 | G15: 12 | H15: 3 | I15: 1,2,1 | J15: 0.75 | K15: 0,0,0,0,0,0,0,0,0,0 | L15: 100 | M15: 0 | N15: 1
A16: funnel_b | E16: T5 | F16: 18 | G16: 12 | H16: 3 | I16: 1,2,1 | J16: 0.75 | K16: 0,0,0,0,0,0,0,0,0,0 | L16: 100 | M16: 0 | N16: 1
A17: funnel_b | B17: 4 | C17: 0 | D17: normal | E17: T1 | F17: 18 | G17: 12 | H17: 3 | I17: 1,2,1 | J17: 0.75 | K17: 0,0,0,0,0,0,0,0,0,0 | L17: 100 | M17: 0 | N17: 1
A18: funnel_b | E18: T2 | F18: 18 | G18: 12 | H18: 3 | I18: 1,2,1 | J18: 0.75 | K18: 0,0,0,0,0,0,0,0,0,0 | L18: 100 | M18: 0 | N18: 1
A19: funnel_b | E19: T3 | F19: 18 | G19: 12 | H19: 3 | I19: 1,2,1 | J19: 0.75 | K19: 0,0,0,0,0,0,0,0,0,0 | L19: 100 | M19: 0 | N19: 1
A20: funnel_b | E20: T4 | F20: 18 | G20: 12 | H20: 3 | I20: 1,2,1 | J20: 0.75 | K20: 0,0,0,0,0,0,0,0,0,0 | L20: 100 | M20: 0 | N20: 1
A21: funnel_b | E21: T5 | F21: 18 | G21: 12 | H21: 3 | I21: 1,2,1 | J21: 0.75 | K21: 0,0,0,0,0,0,0,0,0,0 | L21: 100 | M21: 0 | N21: 1
A22: funnel_b | B22: 5 | C22: 0 | D22: normal | E22: T1 | F22: 18 | G22: 12 | H22: 3 | I22: 1,2,1 | J22: 0.75 | K22: 0,0,0,0,0,0,0,0,0,0 | L22: 100 | M22: 0 | N22: 1
A23: funnel_b | E23: T2 | F23: 18 | G23: 12 | H23: 3 | I23: 1,2,1 | J23: 0.75 | K23: 0,0,0,0,0,0,0,0,0,0 | L23: 100 | M23: 0 | N23: 1
A24: funnel_b | E24: T3 | F24: 18 | G24: 12 | H24: 3 | I24: 1,2,1 | J24: 0.75 | K24: 0,0,0,0,0,0,0,0,0,0 | L24: 100 | M24: 0 | N24: 1
A25: funnel_b | E25: T4 | F25: 18 | G25: 12 | H25: 3 | I25: 1,2,1 | J25: 0.75 | K25: 0,0,0,0,0,0,0,0,0,0 | L25: 100 | M25: 0 | N25: 1
A26: funnel_b | E26: T5 | F26: 18 | G26: 12 | H26: 3 | I26: 1,2,1 | J26: 0.75 | K26: 0,0,0,0,0,0,0,0,0,0 | L26: 100 | M26: 0 | N26: 1
A27: funnel_b | B27: 6 | C27: 0 | D27: normal | E27: T1 | F27: 19 | G27: 12 | H27: 3 | I27: 1,2,1 | J27: 0.75 | K27: 0,0,0,0,0,0,0,0,0,0 | L27: 100 | M27: 0 | N27: 1
A28: funnel_b | E28: T2 | F28: 19 | G28: 12 | H28: 3 | I28: 1,2,1 | J28: 0.75 | K28: 0,0,0,0,0,0,0,0,0,0 | L28: 100 | M28: 0 | N28: 1
A29: funnel_b | E29: T3 | F29: 19 | G29: 12 | H29: 3 | I29: 1,2,1 | J29: 0.75 | K29: 0,0,0,0,0,0,0,0,0,0 | L29: 100 | M29: 0 | N29: 1
A30: funnel_b | E30: T4 | F30: 19 | G30: 12 | H30: 3 | I30: 1,2,1 | J30: 0.75 | K30: 0,0,0,0,0,0,0,0,0,0 | L30: 100 | M30: 0 | N30: 1
A31: funnel_b | E31: T5 | F31: 19 | G31: 12 | H31: 3 | I31: 1,2,1 | J31: 0.75 | K31: 0,0,0,0,0,0,0,0,0,0 | L31: 100 | M31: 0 | N31: 1
A32: funnel_b | B32: 7 | C32: 0 | D32: normal | E32: T1 | F32: 13 | G32: 12 | H32: 3 | I32: 1,2,1 | J32: 0.72 | K32: 0,0,0,0,0,0,0,0,0,0 | L32: 100 | M32: 0 | N32: 1
A33: funnel_b | E33: T2 | F33: 13 | G33: 12 | H33: 3 | I33: 1,2,1 | J33: 0.72 | K33: 0,0,0,0,0,0,0,0,0,0 | L33: 100 | M33: 0 | N33: 1
A34: funnel_b | E34: T3 | F34: 13 | G34: 12 | H34: 3 | I34: 1,2,1 | J34: 0.72 | K34: 0,0,0,0,0,0,0,0,0,0 | L34: 100 | M34: 0 | N34: 1
A35: funnel_b | E35: T4 | F35: 13 | G35: 12 | H35: 3 | I35: 1,2,1 | J35: 0.72 | K35: 0,0,0,0,0,0,0,0,0,0 | L35: 100 | M35: 0 | N35: 1
A36: funnel_b | E36: T5 | F36: 13 | G36: 12 | H36: 3 | I36: 1,2,1 | J36: 0.72 | K36: 0,0,0,0,0,0,0,0,0,0 | L36: 100 | M36: 0 | N36: 1
A37: funnel_b | B37: 8 | C37: 0 | D37: normal | E37: T1 | F37: 7 | G37: 12 | H37: 3 | I37: 1,2,1 | J37: 0.72 | K37: 0.333,0.333,0,0,0,0,0.333,0,0,0 | L37: 93 | M37: 7 | N37: 0.93
A38: funnel_b | E38: T2 | F38: 7 | G38: 12 | H38: 3 | I38: 1,2,1 | J38: 0.72 | K38: 0,0.571,0,0.143,0.143,0,0.143,0,0,0 | L38: 93 | M38: 7 | N38: 0.93
A39: funnel_b | E39: T3 | F39: 7 | G39: 12 | H39: 3 | I39: 1,2,1 | J39: 0.72 | K39: 0,0.286,0,0.143,0,0.143,0,0,0.143,0.286 | L39: 93 | M39: 7 | N39: 0.93
A40: funnel_b | E40: T4 | F40: 7 | G40: 12 | H40: 3 | I40: 1,2,1 | J40: 0.72 | K40: 0,0.286,0,0.143,0,0.143,0,0,0.143,0.286 | L40: 93 | M40: 7 | N40: 0.93
...

Sheet Summary
A1: difficultyLabel | B1: tier | C1: rows | D1: avgWinRate | E1: avgRunCount | F1: avgFailCount
A2: normal | B2: 0 | C2: =COUNTIFS(LevelTierData!D2:D301,A2,LevelTierData!E2:E301,B2) -> 0 | D2: =IF(C2>0,AVERAGEIFS(LevelTierData!O2:O301,LevelTierData!D2:D301,A2,LevelTierData!E2:E301,B2),0) -> 0 | E2: =IF(C2>0,AVERAGEIFS(LevelTierData!L2:L301,LevelTierData!D2:D301,A2,LevelTierData!E2:E301,B2),0) -> 0 | F2: =IF(C2>0,AVERAGEIFS(LevelTierData!N2:N301,LevelTierData!D2:D301,A2,LevelTierData!E2:E301,B2),0) -> 0
A3: normal | B3: 1 | C3: =COUNTIFS(LevelTierData!D2:D301,A3,LevelTierData!E2:E301,B3) -> 42 | D3: =IF(C3>0,AVERAGEIFS(LevelTierData!O2:O301,LevelTierData!D2:D301,A3,LevelTierData!E2:E301,B3),0) -> 0 | E3: =IF(C3>0,AVERAGEIFS(LevelTierData!L2:L301,LevelTierData!D2:D301,A3,LevelTierData!E2:E301,B3),0) -> 0 | F3: =IF(C3>0,AVERAGEIFS(LevelTierData!N2:N301,LevelTierData!D2:D301,A3,LevelTierData!E2:E301,B3),0) -> 0
A4: normal | B4: 2 | C4: =COUNTIFS(LevelTierData!D2:D301,A4,LevelTierData!E2:E301,B4) -> 0 | D4: =IF(C4>0,AVERAGEIFS(LevelTierData!O2:O301,LevelTierData!D2:D301,A4,LevelTierData!E2:E301,B4),0) -> 0 | E4: =IF(C4>0,AVERAGEIFS(LevelTierData!L2:L301,LevelTierData!D2:D301,A4,LevelTierData!E2:E301,B4),0) -> 0 | F4: =IF(C4>0,AVERAGEIFS(LevelTierData!N2:N301,LevelTierData!D2:D301,A4,LevelTierData!E2:E301,B4),0) -> 0
A5: normal | B5: 3 | C5: =COUNTIFS(LevelTierData!D2:D301,A5,LevelTierData!E2:E301,B5) -> 0 | D5: =IF(C5>0,AVERAGEIFS(LevelTierData!O2:O301,LevelTierData!D2:D301,A5,LevelTierData!E2:E301,B5),0) -> 0 | E5: =IF(C5>0,AVERAGEIFS(LevelTierData!L2:L301,LevelTierData!D2:D301,A5,LevelTierData!E2:E301,B5),0) -> 0 | F5: =IF(C5>0,AVERAGEIFS(LevelTierData!N2:N301,LevelTierData!D2:D301,A5,LevelTierData!E2:E301,B5),0) -> 0
A6: normal | B6: 4 | C6: =COUNTIFS(LevelTierData!D2:D301,A6,LevelTierData!E2:E301,B6) -> 0 | D6: =IF(C6>0,AVERAGEIFS(LevelTierData!O2:O301,LevelTierData!D2:D301,A6,LevelTierData!E2:E301,B6),0) -> 0 | E6: =IF(C6>0,AVERAGEIFS(LevelTierData!L2:L301,LevelTierData!D2:D301,A6,LevelTierData!E2:E301,B6),0) -> 0 | F6: =IF(C6>0,AVERAGEIFS(LevelTierData!N2:N301,LevelTierData!D2:D301,A6,LevelTierData!E2:E301,B6),0) -> 0
A7: normal | B7: 5 | C7: =COUNTIFS(LevelTierData!D2:D301,A7,LevelTierData!E2:E301,B7) -> 0 | D7: =IF(C7>0,AVERAGEIFS(LevelTierData!O2:O301,LevelTierData!D2:D301,A7,LevelTierData!E2:E301,B7),0) -> 0 | E7: =IF(C7>0,AVERAGEIFS(LevelTierData!L2:L301,LevelTierData!D2:D301,A7,LevelTierData!E2:E301,B7),0) -> 0 | F7: =IF(C7>0,AVERAGEIFS(LevelTierData!N2:N301,LevelTierData!D2:D301,A7,LevelTierData!E2:E301,B7),0) -> 0
A8: hard | B8: 0 | C8: =COUNTIFS(LevelTierData!D2:D301,A8,LevelTierData!E2:E301,B8) -> 0 | D8: =IF(C8>0,AVERAGEIFS(LevelTierData!O2:O301,LevelTierData!D2:D301,A8,LevelTierData!E2:E301,B8),0) -> 0 | E8: =IF(C8>0,AVERAGEIFS(LevelTierData!L2:L301,LevelTierData!D2:D301,A8,LevelTierData!E2:E301,B8),0) -> 0 | F8: =IF(C8>0,AVERAGEIFS(LevelTierData!N2:N301,LevelTierData!D2:D301,A8,LevelTierData!E2:E301,B8),0) -> 0
A9: hard | B9: 1 | C9: =COUNTIFS(LevelTierData!D2:D301,A9,LevelTierData!E2:E301,B9) -> 4 | D9: =IF(C9>0,AVERAGEIFS(LevelTierData!O2:O301,LevelTierData!D2:D301,A9,LevelTierData!E2:E301,B9),0) -> 0 | E9: =IF(C9>0,AVERAGEIFS(LevelTierData!L2:L301,LevelTierData!D2:D301,A9,LevelTierData!E2:E301,B9),0) -> 0 | F9: =IF(C9>0,AVERAGEIFS(LevelTierData!N2:N301,LevelTierData!D2:D301,A9,LevelTierData!E2:E301,B9),0) -> 0
A10: hard | B10: 2 | C10: =COUNTIFS(LevelTierData!D2:D301,A10,LevelTierData!E2:E301,B10) -> 0 | D10: =IF(C10>0,AVERAGEIFS(LevelTierData!O2:O301,LevelTierData!D2:D301,A10,LevelTierData!E2:E301,B10),0) -> 0 | E10: =IF(C10>0,AVERAGEIFS(LevelTierData!L2:L301,LevelTierData!D2:D301,A10,LevelTierData!E2:E301,B10),0) -> 0 | F10: =IF(C10>0,AVERAGEIFS(LevelTierData!N2:N301,LevelTierData!D2:D301,A10,LevelTierData!E2:E301,B10),0) -> 0
A11: hard | B11: 3 | C11: =COUNTIFS(LevelTierData!D2:D301,A11,LevelTierData!E2:E301,B11) -> 0 | D11: =IF(C11>0,AVERAGEIFS(LevelTierData!O2:O301,LevelTierData!D2:D301,A11,LevelTierData!E2:E301,B11),0) -> 0 | E11: =IF(C11>0,AVERAGEIFS(LevelTierData!L2:L301,LevelTierData!D2:D301,A11,LevelTierData!E2:E301,B11),0) -> 0 | F11: =IF(C11>0,AVERAGEIFS(LevelTierData!N2:N301,LevelTierData!D2:D301,A11,LevelTierData!E2:E301,B11),0) -> 0
A12: hard | B12: 4 | C12: =COUNTIFS(LevelTierData!D2:D301,A12,LevelTierData!E2:E301,B12) -> 0 | D12: =IF(C12>0,AVERAGEIFS(LevelTierData!O2:O301,LevelTierData!D2:D301,A12,LevelTierData!E2:E301,B12),0) -> 0 | E12: =IF(C12>0,AVERAGEIFS(LevelTierData!L2:L301,LevelTierData!D2:D301,A12,LevelTierData!E2:E301,B12),0) -> 0 | F12: =IF(C12>0,AVERAGEIFS(LevelTierData!N2:N301,LevelTierData!D2:D301,A12,LevelTierData!E2:E301,B12),0) -> 0
A13: hard | B13: 5 | C13: =COUNTIFS(LevelTierData!D2:D301,A13,LevelTierData!E2:E301,B13) -> 0 | D13: =IF(C13>0,AVERAGEIFS(LevelTierData!O2:O301,LevelTierData!D2:D301,A13,LevelTierData!E2:E301,B13),0) -> 0 | E13: =IF(C13>0,AVERAGEIFS(LevelTierData!L2:L301,LevelTierData!D2:D301,A13,LevelTierData!E2:E301,B13),0) -> 0 | F13: =IF(C13>0,AVERAGEIFS(LevelTierData!N2:N301,LevelTierData!D2:D301,A13,LevelTierData!E2:E301,B13),0) -> 0
A14: superhard | B14: 0 | C14: =COUNTIFS(LevelTierData!D2:D301,A14,LevelTierData!E2:E301,B14) -> 0 | D14: =IF(C14>0,AVERAGEIFS(LevelTierData!O2:O301,LevelTierData!D2:D301,A14,LevelTierData!E2:E301,B14),0) -> 0 | E14: =IF(C14>0,AVERAGEIFS(LevelTierData!L2:L301,LevelTierData!D2:D301,A14,LevelTierData!E2:E301,B14),0) -> 0 | F14: =IF(C14>0,AVERAGEIFS(LevelTierData!N2:N301,LevelTierData!D2:D301,A14,LevelTierData!E2:E301,B14),0) -> 0
A15: superhard | B15: 1 | C15: =COUNTIFS(LevelTierData!D2:D301,A15,LevelTierData!E2:E301,B15) -> 4 | D15: =IF(C15>0,AVERAGEIFS(LevelTierData!O2:O301,LevelTierData!D2:D301,A15,LevelTierData!E2:E301,B15),0) -> 0 | E15: =IF(C15>0,AVERAGEIFS(LevelTierData!L2:L301,LevelTierData!D2:D301,A15,LevelTierData!E2:E301,B15),0) -> 0 | F15: =IF(C15>0,AVERAGEIFS(LevelTierData!N2:N301,LevelTierData!D2:D301,A15,LevelTierData!E2:E301,B15),0) -> 0
A16: superhard | B16: 2 | C16: =COUNTIFS(LevelTierData!D2:D301,A16,LevelTierData!E2:E301,B16) -> 0 | D16: =IF(C16>0,AVERAGEIFS(LevelTierData!O2:O301,LevelTierData!D2:D301,A16,LevelTierData!E2:E301,B16),0) -> 0 | E16: =IF(C16>0,AVERAGEIFS(LevelTierData!L2:L301,LevelTierData!D2:D301,A16,LevelTierData!E2:E301,B16),0) -> 0 | F16: =IF(C16>0,AVERAGEIFS(LevelTierData!N2:N301,LevelTierData!D2:D301,A16,LevelTierData!E2:E301,B16),0) -> 0
A17: superhard | B17: 3 | C17: =COUNTIFS(LevelTierData!D2:D301,A17,LevelTierData!E2:E301,B17) -> 0 | D17: =IF(C17>0,AVERAGEIFS(LevelTierData!O2:O301,LevelTierData!D2:D301,A17,LevelTierData!E2:E301,B17),0) -> 0 | E17: =IF(C17>0,AVERAGEIFS(LevelTierData!L2:L301,LevelTierData!D2:D301,A17,LevelTierData!E2:E301,B17),0) -> 0 | F17: =IF(C17>0,AVERAGEIFS(LevelTierData!N2:N301,LevelTierData!D2:D301,A17,LevelTierData!E2:E301,B17),0) -> 0
A18: superhard | B18: 4 | C18: =COUNTIFS(LevelTierData!D2:D301,A18,LevelTierData!E2:E301,B18) -> 0 | D18: =IF(C18>0,AVERAGEIFS(LevelTierData!O2:O301,LevelTierData!D2:D301,A18,LevelTierData!E2:E301,B18),0) -> 0 | E18: =IF(C18>0,AVERAGEIFS(LevelTierData!L2:L301,LevelTierData!D2:D301,A18,LevelTierData!E2:E301,B18),0) -> 0 | F18: =IF(C18>0,AVERAGEIFS(LevelTierData!N2:N301,LevelTierData!D2:D301,A18,LevelTierData!E2:E301,B18),0) -> 0
A19: superhard | B19: 5 | C19: =COUNTIFS(LevelTierData!D2:D301,A19,LevelTierData!E2:E301,B19) -> 0 | D19: =IF(C19>0,AVERAGEIFS(LevelTierData!O2:O301,LevelTierData!D2:D301,A19,LevelTierData!E2:E301,B19),0) -> 0 | E19: =IF(C19>0,AVERAGEIFS(LevelTierData!L2:L301,LevelTierData!D2:D301,A19,LevelTierData!E2:E301,B19),0) -> 0 | F19: =IF(C19>0,AVERAGEIFS(LevelTierData!N2:N301,LevelTierData!D2:D301,A19,LevelTierData!E2:E301,B19),0) -> 0
